Workbook
Name SegmentaçãodeDados_Ano: #N/A
Name SegmentaçãodeDados_ATIVO: #N/A
Name SegmentaçãodeDados_ATIVO1: #N/A
Name SegmentaçãodeDados_MÊS: #N/A
Name SegmentaçãodeDados_SEGMENTO: #N/A
Name SegmentaçãodeDados_TIPO: #N/A
Name SegmentaçãodeDados_TIPO1: #N/A

Sheet Dados B3
A1: Código Negociável | B1: Tipo | C1: Razão Social | D1: Valor atual | E1: CNPJ | F1: Segmento | G1: DY | H1: P/VP | I1: Short Name
A2: AMOB3 | B2: Ação | C2: Automob | D2: 11.28 | E2: 35.654.688/0001-08 | F2: Automovéis | G2: 0,00 | H2: 0,00 | I2: AUTOMOB ON NM
A3: ARRI11 | B3: FII | C3: OPEN K ATIVOS E RECEBIVEIS IMOBILIARIOS - FUNDO DE INVESTIMENTO IMOBILIARIO | D3: 6.78 | E3: 32.006.821/0001-21 | F3: CRIs | G3: 15,93 | H3: 0,00 | I3: FII ATRIO CI
A4: BBAS3 | B4: Ação | C4: Banco do Brasil | D4: 23.27 | E4: 00.000.000/0001-91 | G4: 3,58 | H4: 0,00 | I4: BRASIL ON NM
A5: BIME11 | B5: FII | C5: BRIO MULTIESTRATÉGIA - FUNDO DE INVESTIMENTO IMOBILIÁRIO RESPONSABILIDADE LIMITADA | D5: 6.31 | E5: 41.081.356/0001-84 | F5: Híbrido | G5: 15,21 | H5: 0,00 | I5: FII BRIO ME CI
A6: BTHF11 | B6: FII | C6: BTG PACTUAL REAL ESTATE HEDGE FUND FII - FUNDO DE INVESTIMENTO IMOBILIÁRIO RESPONSABILIDADE LIMITADA | D6: 9.29 | E6: 45.188.176/0001-57 | F6: Híbrido | G6: 12,23 | H6: 0,00 | I6: FII BTHF CI
A7: CMIG4 | B7: Ação | C7: Cemig | D7: 12.24 | E7: 17.155.730/0001-64 | F7: Energia Elétrica | G7: 13,49 | H7: 0,00 | I7: CEMIG PN N1
A8: CPSH11 | B8: FII | C8: CAPITÂNIA SHOPPINGS FUNDO DE INVESTIMENTO IMOBILIÁRIO - RESPONSABILIDADE LIMITADA | D8: 10.67 | E8: 47.896.665/0001-99 | F8: Shoppings | G8: 12,18 | H8: 0,00 | I8: FII CPSH CI ER
A9: CPTS11 | B9: FII | C9: CAPITÂNIA SECURITIES II FUNDO DE INVESTIMENTO IMOBILIÁRIO RESPONSABILIDADE LIMITADA | D9: 7.94 | E9: 18.979.895/0001-13 | F9: CRIs | G9: 13,26 | H9: 0,00 | I9: FII CAPI SECCI ER
A10: CURY3 | B10: Ação | C10: Cury | D10: 33.06 | E10: 08.797.760/0001-83 | F10: Construtora | G10: 13,28 | H10: 0,00 | I10: CURY S/A ON NM
A11: CXSE3 | B11: Ação | C11: Caixa Seguridade | D11: 17.35 | E11: 22.543.331/0001-00 | F11: Seguradora | G11: 7,49 | H11: 0,00 | I11: CAIXA SEGURI ON NM
A12: CYRE3 | B12: Ação | C12: Cyrela | D12: 25.05 | E12: 73.178.600/0001-18 | F12: Construtora | G12: 15,17 | H12: 0,00 | I12: CYRELA REALT ON NM
A13: DEVA11 | B13: FII | C13: DEVANT RECEBÍVEIS IMOBILIÁRIOS FUNDO DE INVESTIMENTO IMOBILIÁRIO | D13: 23.35 | E13: 37.087.810/0001-37 | F13: CRIs | G13: 19,53 | H13: 0,00 | I13: FII DEVANT CI
A14: DIRR3 | B14: Ação | C14: Direcional | D14: 13.41 | E14: 16.614.075/0001-00 | F14: Construtora | G14: 16,53 | H14: 0,00 | I14: DIRECIONAL ON NM
A15: EQIR11 | B15: FII | C15: EQI RECEBÍVEIS IMOBILIÁRIOS FUNDO DE INVESTIMENTO IMOBILIÁRIO RESPONSABILIDADE LIMITADA | D15: 8.59 | E15: 41.076.380/0001-25 | F15: CRIs | G15: 15,20 | H15: 0,00 | I15: FII EQI RECECI ER
A16: FYTO11 | B16: FII | C16: FUNDO DE INVESTIMENTO IMOBILIÁRIO - FII FYTO RECEBÍVEIS IMOBILIÁRIOS RESPONSABILIDADE LIMITADA | D16: 8.44 | E16: 18.085.673/0001-57 | F16: CRIs | G16: 14,50 | H16: 0,00 | I16: FII FYTO CI
... A36: XPML11 | B36: FII | C36: XP MALLS FUNDO DE INVESTIMENTO IMOBILIÁRIO FII | D36: 108.45 | E36: 28.757.546/0001-00 | F36: Shoppings | G36: 10,19 | H36: 0,00 | I36: FII XP MALLSCI ER
A37: SARE11 | B37: FII | C37: SANTANDER RENDA DE ALUGUÉIS FUNDO DE INVESTIMENTO IMOBILIÁRIO - FII - RESP LIMITADA | D37: 4.75 | E37: 32.903.702/0001-71 | F37: Híbrido | G37: 2,17 | H37: 0,00
A38: SANB4 | B38: Ação | C38: Banco Santander | D38: 15.44 | E38: 90.400.888/0001-42 | F38: Bancário | G38: 7,35 | H38: 0,00
A39: KNRI11 | B39: FII | C39: KINEA RENDA IMOBILIÁRIA FUNDO DE INVESTIMENTO IMOBILIÁRIO RESPONSABILIDADE LIMITADA | D39: 164.73 | E39: 12.005.956/0001-65 | F39: Híbrido | G39: 7,40 | H39: 0,00
A40: ABCP11 | B40: FII | C40: GRAND PLAZA SHOPPING FUNDO DE INVESTIMENTO IMOBILIÁRIO - RESPONSABILIDADE LIMITADA | D40: 80.01 | E40: 01.201.140/0001-90 | F40: Shoppings | G40: 9,76 | H40: 0,00
A41: ALZR11 | B41: FII | C41: ALIANZA TRUST RENDA IMOBILIÁRIA - FUNDO DE INVESTIMENTO IMOBILIÁRIO RESPONSABILIDADE LIMITADA | D41: 10.71 | E41: 28.737.771/0001-85 | F41: Híbrido | G41: 9,36 | H41: 0,00
A42: AGRX11 | B42: FII | D42: 8.97 | F42: Fiagro | G42: 0,00 | H42: 0,00
A43: MXRF11 | B43: FII | C43: MAXI RENDA FUNDO DE INVESTIMENTO IMOBILIÁRIO - FII - RESPONSABILIDADE LIMITADA | D43: 9.69 | E43: 97.521.225/0001-25 | F43: CRIs | G43: 12,27 | H43: 0,00
A44: BTLG11 | B44: FII | C44: BTG PACTUAL LOGÍSTICA FUNDO DE INVESTIMENTO IMOBILIÁRIO RESPONSABILIDADE LIMITADA | D44: 103.87 | E44: 11.839.593/0001-09 | F44: Logística | G44: 9,09 | H44: 0,00
A45: GRWA11 | B45: FII | C45: GREENWICH AGRO FIAGRO | D45: 8.05 | E45: 47.240.671/0001-93 | F45: Fiagro | G45: 0,00 | H45: 0,00
A46: RURA11 | B46: FII | C46: ITAU ASSET RURAL FIAGRO | D46: 8.98 | E46: 42.479.593/0001-60 | F46: Fiagro | G46: 0,00 | H46: 0,00
A47: INLG11 | B47: FII | C47: INTER LOGÍSTICO FUNDO DE INVESTIMENTO IMOBILIÁRIO FII RESPONSABILIDADE LIMITADA | D47: 74.33 | E47: 34.598.181/0001-11 | F47: Logística | G47: 11,74 | H47: 0,00
A48: XPCI11 | B48: FII | C48: XP CRÉDITO IMOBILIÁRIO - FUNDO DE INVESTIMENTO IMOBILIÁRIO | D48: 83.95 | E48: 28.516.301/0001-91 | F48: CRIs | G48: 12,96 | H48: 0,00
A49: APTO11 | B49: FII | C49: NAVI RESIDENCIAL FUNDO DE INVESTIMENTO IMOBILIÁRIO - RESPONSABILIDADE LIMITADA | D49: 8.42 | E49: 42.432.327/0001-82 | F49: Híbrido | G49: 12,72 | H49: 0,00
A50: VGHF11 | B50: FII | C50: VALORA HEDGE FUND FUNDO DE INVESTIMENTO IMOBILIÁRIO DE RESPONSABILIDADE LIMITADA | D50: 7.09 | E50: 36.771.692/0001-19 | F50: CRIs | G50: 13,84 | H50: 0,00
A51: VGIR11 | B51: FII | C51: VALORA CRI CDI FUNDO DE INVESTIMENTO IMOBILIÁRIO - FII RESPONSABILIDADE LIMITADA | D51: 9.72 | E51: 29.852.732/0001-91 | F51: CRIs | G51: 15,62 | H51: 0,00
A52: VGIA11 | B52: FII | D52: 9.82 | F52: Fiagro | G52: 0,00
A53: IRDM11 | B53: FII | C53: FUNDO DE INVESTIMENTO IMOBILIÁRIO IRIDIUM RECEBÍVEIS IMOBILIÁRIOS RESPONSABILIDADE LIMITADA | D53: 58.5 | E53: 28.830.325/0001-10 | F53: CRIs | G53: 11,49
A54: VSLH11 | B54: FII | C54: VERSALHES RECEBÍVEIS IMOBILIÁRIOS FUNDO DE INVESTIMENTO IMOBILIÁRIO DE RESPONSABILIDADE LIMITADA | D54: 2.13 | E54: 36.244.015/0001-42 | F54: CRIs | G54: 16,90 | H54: 0,00
A55: BIDB11 | B55: FII | C55: INTER INFRA FIC INFRA RENDA FIXA CRÉDITO PRIVADO | D55: 81.3 | E55: 42.294.971/0001-31 | F55: FI-Infra | G55: 0,00
A56: ALZC11 | B56: FII | C56: ALIANZA CRÉDITO IMOBILIÁRIO FUNDO DE INVESTIMENTO IMOBILIÁRIO RESPONSABILIDADE LIMITADA | D56: 7.93 | E56: 40.011.324/0001-40 | F56: CRIs | G56: 16,44
A57: AERO11 | B57: FII | C57: HCO OPPS AERO I FII DE RESPONSABILIDADE LIMITADA | D57: 100.01 | G57: 0,00
A58: AFHF11 | B58: FII | C58: AF INVEST REAL ESTATE MULTIESTRATÉGIA FUNDO DE INVESTIMENTO IMOBILIÁRIO - RESPONSABILIDADE LIMITADA | D58: 10.04 | G58: 0,00
A59: AFHI11 | B59: FII | C59: AF INVEST CRI FUNDO DE INVESTIMENTO IMOBILIÁRIO RECEBÍVEIS IMOBILIÁRIOS RESPONSABILIDADE LIMITADA | D59: 96.15 | E59: 36.642.293/0001-58 | F59: CRIs | G59: 13,59
...

Sheet APORTES
A1: Data | B1: Valor | C1: Descrição | F1: TOTAL: | G1: =SUBTOTAL(9,B:B)
A2: 45111 | B2: 16.53
A3: 45168 | B3: 0.26
A4: 45225 | B4: 10
A5: 45239 | B5: 10
A6: 45247 | B6: 0.65
A7: 45259 | B7: 26.2
A8: 45313 | B8: 0.32
A9: 45371 | B9: 3.8
A10: 45407 | B10: 17
A11: 45428 | B11: 5
A12: 45467 | B12: 4.6
A13: 45495 | B13: 6.37
... A35: 45880 | B35: 300
A36: 45894 | B36: 459.3 | C36: Ajuste de saldo
A37: 45917 | B37: 100
A38: 45953 | B38: 110
A39: 45974 | B39: 110.59
A40: 45696 | B40: -331.77 | C40: Transferência Tesouro Direto
A41: 46020 | B41: 400
A42: 46027 | B42: 500
A43: 743.1 | B43: 743.1
A44: 46020 | B44: 600.59

Sheet DIVIDENDOS
A1: Ano | B1: Data Pagamento | C1: MÊS | D1: Liquidação | E1: Valor | F1: PROVENTOS | G1: ATIVO | I1: TOTAL RECEBIDO: | J1: =SUBTOTAL(9,E$1:E$1443)
A2: =YEAR(DIVIDENDOS[[#This Row],[Data Pagamento]]) | B2: 45261 | C2: =IFERROR(IF(DIVIDENDOS[[#This Row],[Data Pagamento]]="","",EOMONTH(B2,0)),"") | D2: =IFERROR(IF(DIVIDENDOS[[#This Row],[Data Pagamento]]="","",DIVIDENDOS[[#This Row],[Data Pagamento]]),"") | E2: 0.87 | F2: RENDIMENTO | G2: AAZQ11
A3: =YEAR(DIVIDENDOS[[#This Row],[Data Pagamento]]) | B3: 45261 | C3: =IFERROR(IF(DIVIDENDOS[[#This Row],[Data Pagamento]]="","",EOMONTH(B3,0)),"") | D3: =IFERROR(IF(DIVIDENDOS[[#This Row],[Data Pagamento]]="","",DIVIDENDOS[[#This Row],[Data Pagamento]]),"") | E3: 0.45 | F3: RENDIMENTO | G3: AGRX11
A4: =YEAR(DIVIDENDOS[[#This Row],[Data Pagamento]]) | B4: 45261 | C4: =IFERROR(IF(DIVIDENDOS[[#This Row],[Data Pagamento]]="","",EOMONTH(B4,0)),"") | D4: =IFERROR(IF(DIVIDENDOS[[#This Row],[Data Pagamento]]="","",DIVIDENDOS[[#This Row],[Data Pagamento]]),"") | E4: 1.73 | F4: RENDIMENTO | G4: ARRI11
A5: =YEAR(DIVIDENDOS[[#This Row],[Data Pagamento]]) | B5: 45261 | C5: =IFERROR(IF(DIVIDENDOS[[#This Row],[Data Pagamento]]="","",EOMONTH(B5,0)),"") | D5: =IFERROR(IF(DIVIDENDOS[[#This Row],[Data Pagamento]]="","",DIVIDENDOS[[#This Row],[Data Pagamento]]),"") | E5: 0.2 | F5: RENDIMENTO | G5: BIME11
A6: =YEAR(DIVIDENDOS[[#This Row],[Data Pagamento]]) | B6: 45261 | C6: =IFERROR(IF(DIVIDENDOS[[#This Row],[Data Pagamento]]="","",EOMONTH(B6,0)),"") | D6: =IFERROR(IF(DIVIDENDOS[[#This Row],[Data Pagamento]]="","",DIVIDENDOS[[#This Row],[Data Pagamento]]),"") | E6: 0.36 | F6: RENDIMENTO | G6: BLMR11
A7: =YEAR(DIVIDENDOS[[#This Row],[Data Pagamento]]) | B7: 45261 | C7: =IFERROR(IF(DIVIDENDOS[[#This Row],[Data Pagamento]]="","",EOMONTH(B7,0)),"") | D7: =IFERROR(IF(DIVIDENDOS[[#This Row],[Data Pagamento]]="","",DIVIDENDOS[[#This Row],[Data Pagamento]]),"") | E7: 0.31 | F7: RENDIMENTO | G7: BODB11
A8: =YEAR(DIVIDENDOS[[#This Row],[Data Pagamento]]) | B8: 45261 | C8: =IFERROR(IF(DIVIDENDOS[[#This Row],[Data Pagamento]]="","",EOMONTH(B8,0)),"") | D8: =IFERROR(IF(DIVIDENDOS[[#This Row],[Data Pagamento]]="","",DIVIDENDOS[[#This Row],[Data Pagamento]]),"") | E8: 4.01 | F8: RENDIMENTO | G8: MRXF11
A9: =YEAR(DIVIDENDOS[[#This Row],[Data Pagamento]]) | B9: 45261 | C9: =IFERROR(IF(DIVIDENDOS[[#This Row],[Data Pagamento]]="","",EOMONTH(B9,0)),"") | D9: =IFERROR(IF(DIVIDENDOS[[#This Row],[Data Pagamento]]="","",DIVIDENDOS[[#This Row],[Data Pagamento]]),"") | E9: 0.59 | F9: RENDIMENTO | G9: RURA11
A10: =YEAR(DIVIDENDOS[[#This Row],[Data Pagamento]]) | B10: 45261 | C10: =IFERROR(IF(DIVIDENDOS[[#This Row],[Data Pagamento]]="","",EOMONTH(B10,0)),"") | D10: =IFERROR(IF(DIVIDENDOS[[#This Row],[Data Pagamento]]="","",DIVIDENDOS[[#This Row],[Data Pagamento]]),"") | E10: 9.99 | F10: RENDIMENTO | G10: XPML11
A11: =YEAR(DIVIDENDOS[[#This Row],[Data Pagamento]]) | B11: 45627 | C11: =IFERROR(IF(DIVIDENDOS[[#This Row],[Data Pagamento]]="","",EOMONTH(B11,0)),"") | D11: =IFERROR(IF(DIVIDENDOS[[#This Row],[Data Pagamento]]="","",DIVIDENDOS[[#This Row],[Data Pagamento]]),"") | E11: 5.74 | F11: RENDIMENTO | G11: AAZQ11
A12: =YEAR(DIVIDENDOS[[#This Row],[Data Pagamento]]) | B12: 45627 | C12: =IFERROR(IF(DIVIDENDOS[[#This Row],[Data Pagamento]]="","",EOMONTH(B12,0)),"") | D12: =IFERROR(IF(DIVIDENDOS[[#This Row],[Data Pagamento]]="","",DIVIDENDOS[[#This Row],[Data Pagamento]]),"") | E12: 3.86 | F12: RENDIMENTO | G12: ALZM11
A13: =YEAR(DIVIDENDOS[[#This Row],[Data Pagamento]]) | B13: 45627 | C13: =IFERROR(IF(DIVIDENDOS[[#This Row],[Data Pagamento]]="","",EOMONTH(B13,0)),"") | D13: =IFERROR(IF(DIVIDENDOS[[#This Row],[Data Pagamento]]="","",DIVIDENDOS[[#This Row],[Data Pagamento]]),"") | E13: 4.19 | F13: RENDIMENTO | G13: ARRI11
... A130: =YEAR(DIVIDENDOS[[#This Row],[Data Pagamento]]) | B130: 46014 | C130: =IFERROR(IF(DIVIDENDOS[[#This Row],[Data Pagamento]]="","",EOMONTH(B130,0)),"") | D130: =IFERROR(IF(DIVIDENDOS[[#This Row],[Data Pagamento]]="","",DIVIDENDOS[[#This Row],[Data Pagamento]]),"") | E130: 1.67 | F130: RENDIMENTO | G130: ALZR11
A131: 2026 | B131: 46014 | C131: =IFERROR(IF(DIVIDENDOS[[#This Row],[Data Pagamento]]="","",EOMONTH(B131,0)),"") | D131: =IFERROR(IF(DIVIDENDOS[[#This Row],[Data Pagamento]]="","",DIVIDENDOS[[#This Row],[Data Pagamento]]),"") | E131: 7.5 | F131: RENDIMENTO | G131: CPSH11
A132: 2026 | B132: 46014 | C132: =IFERROR(IF(DIVIDENDOS[[#This Row],[Data Pagamento]]="","",EOMONTH(B132,0)),"") | D132: =IFERROR(IF(DIVIDENDOS[[#This Row],[Data Pagamento]]="","",DIVIDENDOS[[#This Row],[Data Pagamento]]),"") | E132: 1.3 | F132: RENDIMENTO | G132: SNAG11
A133: 2026 | B133: 46014 | C133: =IFERROR(IF(DIVIDENDOS[[#This Row],[Data Pagamento]]="","",EOMONTH(B133,0)),"") | D133: =IFERROR(IF(DIVIDENDOS[[#This Row],[Data Pagamento]]="","",DIVIDENDOS[[#This Row],[Data Pagamento]]),"") | E133: 1.84 | F133: RENDIMENTO | G133: XPML11
A134: 2026 | B134: 46017 | C134: =IFERROR(IF(DIVIDENDOS[[#This Row],[Data Pagamento]]="","",EOMONTH(B134,0)),"") | D134: =IFERROR(IF(DIVIDENDOS[[#This Row],[Data Pagamento]]="","",DIVIDENDOS[[#This Row],[Data Pagamento]]),"") | E134: 3 | F134: RENDIMENTO | G134: EQIR11
A135: 2026 | B135: 46021 | C135: =IFERROR(IF(DIVIDENDOS[[#This Row],[Data Pagamento]]="","",EOMONTH(B135,0)),"") | D135: =IFERROR(IF(DIVIDENDOS[[#This Row],[Data Pagamento]]="","",DIVIDENDOS[[#This Row],[Data Pagamento]]),"") | E135: 0.98 | F135: DIVIDENDOS | G135: CMIG4
A136: 2026 | B136: 46021 | C136: =IFERROR(IF(DIVIDENDOS[[#This Row],[Data Pagamento]]="","",EOMONTH(B136,0)),"") | D136: =IFERROR(IF(DIVIDENDOS[[#This Row],[Data Pagamento]]="","",DIVIDENDOS[[#This Row],[Data Pagamento]]),"") | E136: 0.44 | F136: DIVIDENDOS | G136: CMIG4
A137: 2025 | B137: 09/12/2025 | C137: =IFERROR(IF(DIVIDENDOS[[#This Row],[Data Pagamento]]="","",EOMONTH(B137,0)),"") | D137: =IFERROR(IF(DIVIDENDOS[[#This Row],[Data Pagamento]]="","",DIVIDENDOS[[#This Row],[Data Pagamento]]),"") | E137: 17.22 | F137: RENDIMENTO | G137: IRDM11
A138: 2025 | B138: 12/12/2025 | C138: =IFERROR(IF(DIVIDENDOS[[#This Row],[Data Pagamento]]="","",EOMONTH(B138,0)),"") | D138: =IFERROR(IF(DIVIDENDOS[[#This Row],[Data Pagamento]]="","",DIVIDENDOS[[#This Row],[Data Pagamento]]),"") | E138: 2 | F138: RENDIMENTO | G138: BIDB11
A139: 2025 | B139: 12/12/2025 | C139: =IFERROR(IF(DIVIDENDOS[[#This Row],[Data Pagamento]]="","",EOMONTH(B139,0)),"") | D139: =IFERROR(IF(DIVIDENDOS[[#This Row],[Data Pagamento]]="","",DIVIDENDOS[[#This Row],[Data Pagamento]]),"") | E139: 1.46 | F139: RENDIMENTO | G139: INLG11
A140: 2025 | B140: 12/12/2025 | C140: =IFERROR(IF(DIVIDENDOS[[#This Row],[Data Pagamento]]="","",EOMONTH(B140,0)),"") | D140: =IFERROR(IF(DIVIDENDOS[[#This Row],[Data Pagamento]]="","",DIVIDENDOS[[#This Row],[Data Pagamento]]),"") | E140: 0.45 | F140: JUROS | G140: ISAE4
A141: 2025 | B141: 14/10/2025 | C141: =IFERROR(IF(DIVIDENDOS[[#This Row],[Data Pagamento]]="","",EOMONTH(B141,0)),"") | D141: =IFERROR(IF(DIVIDENDOS[[#This Row],[Data Pagamento]]="","",DIVIDENDOS[[#This Row],[Data Pagamento]]),"") | E141: 1.5 | F141: RENDIMENTO | G141: INLG11
A142: 2025 | B142: 14/11/2025 | C142: =IFERROR(IF(DIVIDENDOS[[#This Row],[Data Pagamento]]="","",EOMONTH(B142,0)),"") | D142: =IFERROR(IF(DIVIDENDOS[[#This Row],[Data Pagamento]]="","",DIVIDENDOS[[#This Row],[Data Pagamento]]),"") | E142: 1.48 | F142: RENDIMENTO | G142: INLG11
A143: =YEAR(DIVIDENDOS[[#This Row],[Data Pagamento]]) | B143: 28/11/2025 | C143: =IFERROR(IF(DIVIDENDOS[[#This Row],[Data Pagamento]]="","",EOMONTH(B143,0)),"") | D143: =IFERROR(IF(DIVIDENDOS[[#This Row],[Data Pagamento]]="","",DIVIDENDOS[[#This Row],[Data Pagamento]]),"") | E143: 0.45 | F143: JUROS | G143: ISAE4
A144: =YEAR(DIVIDENDOS[[#This Row],[Data Pagamento]]) | B144: 30/12/2025 | C144: =IFERROR(IF(DIVIDENDOS[[#This Row],[Data Pagamento]]="","",EOMONTH(B144,0)),"") | D144: =IFERROR(IF(DIVIDENDOS[[#This Row],[Data Pagamento]]="","",DIVIDENDOS[[#This Row],[Data Pagamento]]),"") | E144: 0.45 | F144: JUROS | G144: ISAE4
A145: 2026 | B145: 13/03/2026 | C145: =IFERROR(IF(DIVIDENDOS[[#This Row],[Data Pagamento]]="","",EOMONTH(B145,0)),"") | D145: =IFERROR(IF(DIVIDENDOS[[#This Row],[Data Pagamento]]="","",DIVIDENDOS[[#This Row],[Data Pagamento]]),"") | E145: 2.1 | F145: RENDIMENTO | G145: AAZQ11
A146: 2026 | B146: 13/02/2026 | C146: =IFERROR(IF(DIVIDENDOS[[#This Row],[Data Pagamento]]="","",EOMONTH(B146,0)),"") | D146: =IFERROR(IF(DIVIDENDOS[[#This Row],[Data Pagamento]]="","",DIVIDENDOS[[#This Row],[Data Pagamento]]),"") | E146: 2.1 | F146: RENDIMENTO | G146: AAZQ11
A147: 2026 | B147: 15/01/2026 | C147: =IFERROR(IF(DIVIDENDOS[[#This Row],[Data Pagamento]]="","",EOMONTH(B147,0)),"") | D147: =IFERROR(IF(DIVIDENDOS[[#This Row],[Data Pagamento]]="","",DIVIDENDOS[[#This Row],[Data Pagamento]]),"") | E147: 2.65 | F147: RENDIMENTO | G147: AAZQ11
A148: 2026 | B148: 25/02/2026 | C148: =IFERROR(IF(DIVIDENDOS[[#This Row],[Data Pagamento]]="","",EOMONTH(B148,0)),"") | D148: =IFERROR(IF(DIVIDENDOS[[#This Row],[Data Pagamento]]="","",DIVIDENDOS[[#This Row],[Data Pagamento]]),"") | E148: 3.34 | F148: RENDIMENTO | G148: ALZR11
A149: 2026 | B149: 23/01/2026 | C149: =IFERROR(IF(DIVIDENDOS[[#This Row],[Data Pagamento]]="","",EOMONTH(B149,0)),"") | D149: =IFERROR(IF(DIVIDENDOS[[#This Row],[Data Pagamento]]="","",DIVIDENDOS[[#This Row],[Data Pagamento]]),"") | E149: 3.4 | F149: RENDIMENTO | G149: ALZR11
A150: 2026 | B150: 06/03/2026 | C150: =IFERROR(IF(DIVIDENDOS[[#This Row],[Data Pagamento]]="","",EOMONTH(B150,0)),"") | D150: =IFERROR(IF(DIVIDENDOS[[#This Row],[Data Pagamento]]="","",DIVIDENDOS[[#This Row],[Data Pagamento]]),"") | E150: 3.6 | F150: RENDIMENTO | G150: ARRI11
A151: 2026 | B151: 06/02/2026 | C151: =IFERROR(IF(DIVIDENDOS[[#This Row],[Data Pagamento]]="","",EOMONTH(B151,0)),"") | D151: =IFERROR(IF(DIVIDENDOS[[#This Row],[Data Pagamento]]="","",DIVIDENDOS[[#This Row],[Data Pagamento]]),"") | E151: 3.6 | F151: RENDIMENTO | G151: ARRI11
A152: 2026 | B152: 08/01/2026 | C152: =IFERROR(IF(DIVIDENDOS[[#This Row],[Data Pagamento]]="","",EOMONTH(B152,0)),"") | D152: =IFERROR(IF(DIVIDENDOS[[#This Row],[Data Pagamento]]="","",DIVIDENDOS[[#This Row],[Data Pagamento]]),"") | E152: 3.6 | F152: RENDIMENTO | G152: ARRI11
A153: 2026 | B153: 11/03/2026 | C153: =IFERROR(IF(DIVIDENDOS[[#This Row],[Data Pagamento]]="","",EOMONTH(B153,0)),"") | D153: =IFERROR(IF(DIVIDENDOS[[#This Row],[Data Pagamento]]="","",DIVIDENDOS[[#This Row],[Data Pagamento]]),"") | E153: 0.21 | F153: JUROS | G153: BBAS3
A154: 2026 | B154: 05/03/2026 | C154: =IFERROR(IF(DIVIDENDOS[[#This Row],[Data Pagamento]]="","",EOMONTH(B154,0)),"") | D154: =IFERROR(IF(DIVIDENDOS[[#This Row],[Data Pagamento]]="","",DIVIDENDOS[[#This Row],[Data Pagamento]]),"") | E154: 0.02 | F154: RENDIMENTO | G154: BBAS3
A155: 2026 | B155: 13/03/2026 | C155: =IFERROR(IF(DIVIDENDOS[[#This Row],[Data Pagamento]]="","",EOMONTH(B155,0)),"") | D155: =IFERROR(IF(DIVIDENDOS[[#This Row],[Data Pagamento]]="","",DIVIDENDOS[[#This Row],[Data Pagamento]]),"") | E155: 2 | F155: RENDIMENTO | G155: BIDB11
A156: 2026 | B156: 13/02/2026 | C156: =IFERROR(IF(DIVIDENDOS[[#This Row],[Data Pagamento]]="","",EOMONTH(B156,0)),"") | D156: =IFERROR(IF(DIVIDENDOS[[#This Row],[Data Pagamento]]="","",DIVIDENDOS[[#This Row],[Data Pagamento]]),"") | E156: 2 | F156: RENDIMENTO | G156: BIDB11
...

Sheet OPERAÇÕES
A1: Data | B1: Ticker | C1: Quantidade | D1: Valor (Preço unitário) | E1: TIPO | F1: Qtde execut. | G1: Valor Total | H1: Operação | I1: Qdo vender, aqui VL. real | J1: VL. Total vendas | K1: Lucro/Prej. | M1: Total Investido | N1: =SUBTOTAL(9,G:G) | P1: Operações | R1: Total vendas | S1: =SUBTOTAL(9,J:J) | U1: Total Lucro/Prejuízo | V1: =SUBTOTAL(9,K:K)
A2: 45748 | B2: Tesouro | C2: 1 | D2: 163.07 | E2: =IFERROR(VLOOKUP(B2,'Dados B3'!A:G,2,FALSE),"-") | F2: =IF(H2=P$4,(C2*(1)),IF(H2=P$3,(C2*(-1)),IF(H2=P$2,(C2*(1))))) | G2: =F2*D2 | H2: VENDA | I2: 4.25 | J2: =IF(H2="VENDA",I2*F2*-1,0) | K2: =IF(J2=0,0,J2+G2) | P2: COMPRA
A3: 45748 | B3: Tesouro | C3: 1 | D3: 70.91 | E3: =IFERROR(VLOOKUP(B3,'Dados B3'!A:G,2,FALSE),"-") | F3: =IF(H3=P$4,(C3*(1)),IF(H3=P$3,(C3*(-1)),IF(H3=P$2,(C3*(1))))) | G3: =F3*D3 | H3: VENDA | J3: =IF(H3="VENDA",I3*F3*-1,0) | K3: =IF(J3=0,0,J3+G3) | M3: OBS.: TODA VEZ QUE REALIZAR UMA VENDA, DIGITAR O VALOR EXECUTADO DE VENDA COMO O PREÇO MÉDIO, DIGITAR A QTDE VENDIDA NORMALMENTE. ASSIM, A QTDE ATUAL E O PREÇO MÉDIO CONTINUARÁ COM OS VALORES CORRETOS | P3: VENDA
A4: 45748 | B4: Tesouro | C4: 1 | D4: 33.3 | E4: =IFERROR(VLOOKUP(B4,'Dados B3'!A:G,2,FALSE),"-") | F4: =IF(H4=P$4,(C4*(1)),IF(H4=P$3,(C4*(-1)),IF(H4=P$2,(C4*(1))))) | G4: =F4*D4 | H4: COMPRA | I4: 0 | J4: =IF(H4="VENDA",I4*F4*-1,0) | K4: =IF(J4=0,0,J4+G4) | P4: AJUSTE
A5: 45748 | B5: Tesouro | C5: 1 | D5: 41.39 | E5: =IFERROR(VLOOKUP(B5,'Dados B3'!A:G,2,FALSE),"-") | F5: =IF(H5=P$4,(C5*(1)),IF(H5=P$3,(C5*(-1)),IF(H5=P$2,(C5*(1))))) | G5: =F5*D5 | H5: COMPRA | J5: =IF(H5="VENDA",I5*F5*-1,0) | K5: =IF(J5=0,0,J5+G5)
A6: 45748 | B6: Tesouro | C6: 1 | D6: 16.08 | E6: =IFERROR(VLOOKUP(B6,'Dados B3'!A:G,2,FALSE),"-") | F6: =IF(H6=P$4,(C6*(1)),IF(H6=P$3,(C6*(-1)),IF(H6=P$2,(C6*(1))))) | G6: =F6*D6 | H6: COMPRA | J6: =IF(H6="VENDA",I6*F6*-1,0) | K6: =IF(J6=0,0,J6+G6)
A7: 45748 | B7: Tesouro | C7: 1 | D7: 7.02 | E7: =IFERROR(VLOOKUP(B7,'Dados B3'!A:G,2,FALSE),"-") | F7: =IF(H7=P$4,(C7*(1)),IF(H7=P$3,(C7*(-1)),IF(H7=P$2,(C7*(1))))) | G7: =F7*D7 | H7: COMPRA | J7: =IF(H7="VENDA",I7*F7*-1,0) | K7: =IF(J7=0,0,J7+G7)
A8: 45894 | B8: CPSH11 | C8: 50 | D8: 9.47 | E8: =IFERROR(VLOOKUP(B8,'Dados B3'!A:G,2,FALSE),"-") | F8: =IF(H8=P$4,(C8*(1)),IF(H8=P$3,(C8*(-1)),IF(H8=P$2,(C8*(1))))) | G8: =F8*D8 | H8: COMPRA | J8: =IF(H8="VENDA",I8*F8*-1,0) | K8: =IF(J8=0,0,J8+G8)
A9: 45894 | B9: GARE11 | C9: 51 | D9: 8.45 | E9: =IFERROR(VLOOKUP(B9,'Dados B3'!A:G,2,FALSE),"-") | F9: =IF(H9=P$4,(C9*(1)),IF(H9=P$3,(C9*(-1)),IF(H9=P$2,(C9*(1))))) | G9: =F9*D9 | H9: COMPRA | J9: =IF(H9="VENDA",I9*F9*-1,0) | K9: =IF(J9=0,0,J9+G9)
A10: 45894 | B10: BIME11 | C10: 65 | D10: 6.82 | E10: =IFERROR(VLOOKUP(B10,'Dados B3'!A:G,2,FALSE),"-") | F10: =IF(H10=P$4,(C10*(1)),IF(H10=P$3,(C10*(-1)),IF(H10=P$2,(C10*(1))))) | G10: =F10*D10 | H10: COMPRA | J10: =IF(H10="VENDA",I10*F10*-1,0) | K10: =IF(J10=0,0,J10+G10)
A11: 45894 | B11: FYTO11 | C11: 50 | D11: 7.77 | E11: =IFERROR(VLOOKUP(B11,'Dados B3'!A:G,2,FALSE),"-") | F11: =IF(H11=P$4,(C11*(1)),IF(H11=P$3,(C11*(-1)),IF(H11=P$2,(C11*(1))))) | G11: =F11*D11 | H11: COMPRA | J11: =IF(H11="VENDA",I11*F11*-1,0) | K11: =IF(J11=0,0,J11+G11)
A12: 45894 | B12: ARRI11 | C12: 50 | D12: 7.45 | E12: =IFERROR(VLOOKUP(B12,'Dados B3'!A:G,2,FALSE),"-") | F12: =IF(H12=P$4,(C12*(1)),IF(H12=P$3,(C12*(-1)),IF(H12=P$2,(C12*(1))))) | G12: =F12*D12 | H12: COMPRA | J12: =IF(H12="VENDA",I12*F12*-1,0) | K12: =IF(J12=0,0,J12+G12)
A13: 45894 | B13: TEPP11 | C13: 4 | D13: 81.63 | E13: =IFERROR(VLOOKUP(B13,'Dados B3'!A:G,2,FALSE),"-") | F13: =IF(H13=P$4,(C13*(1)),IF(H13=P$3,(C13*(-1)),IF(H13=P$2,(C13*(1))))) | G13: =F13*D13 | H13: COMPRA | J13: =IF(H13="VENDA",I13*F13*-1,0) | K13: =IF(J13=0,0,J13+G13)
A14: 45894 | B14: TRXF11 | C14: 3 | D14: 99.63 | E14: =IFERROR(VLOOKUP(B14,'Dados B3'!A:G,2,FALSE),"-") | F14: =IF(H14=P$4,(C14*(1)),IF(H14=P$3,(C14*(-1)),IF(H14=P$2,(C14*(1))))) | G14: =F14*D14 | H14: COMPRA | J14: =IF(H14="VENDA",I14*F14*-1,0) | K14: =IF(J14=0,0,J14+G14)
A15: 45894 | B15: DEVA11 | C15: 10 | D15: 29.19 | E15: =IFERROR(VLOOKUP(B15,'Dados B3'!A:G,2,FALSE),"-") | F15: =IF(H15=P$4,(C15*(1)),IF(H15=P$3,(C15*(-1)),IF(H15=P$2,(C15*(1))))) | G15: =F15*D15 | H15: COMPRA | J15: =IF(H15="VENDA",I15*F15*-1,0) | K15: =IF(J15=0,0,J15+G15)
A16: 45894 | B16: LIFE11 | C16: 30 | D16: 8.81 | E16: =IFERROR(VLOOKUP(B16,'Dados B3'!A:G,2,FALSE),"-") | F16: =IF(H16=P$4,(C16*(1)),IF(H16=P$3,(C16*(-1)),IF(H16=P$2,(C16*(1))))) | G16: =F16*D16 | H16: COMPRA | J16: =IF(H16="VENDA",I16*F16*-1,0) | K16: =IF(J16=0,0,J16+G16)
... A38: 45894 | B38: CSNA3 | C38: 10 | D38: 8.3 | E38: =IFERROR(VLOOKUP(B38,'Dados B3'!A:G,2,FALSE),"-") | F38: =IF(H38=P$4,(C38*(1)),IF(H38=P$3,(C38*(-1)),IF(H38=P$2,(C38*(1))))) | G38: =F38*D38 | H38: COMPRA | J38: =IF(H38="VENDA",I38*F38*-1,0) | K38: =IF(J38=0,0,J38+G38)
A39: 45894 | B39: DIVD11 | C39: 1 | D39: 51.04 | E39: =IFERROR(VLOOKUP(B39,'Dados B3'!A:G,2,FALSE),"-") | F39: =IF(H39=P$4,(C39*(1)),IF(H39=P$3,(C39*(-1)),IF(H39=P$2,(C39*(1))))) | G39: =F39*D39 | H39: VENDA | I39: 15.01 | J39: =IF(H39="VENDA",I39*F39*-1,0) | K39: =IF(J39=0,0,J39+G39)
A40: 45894 | B40: BBDC4 | C40: 2 | D40: 12.64 | E40: =IFERROR(VLOOKUP(B40,'Dados B3'!A:G,2,FALSE),"-") | F40: =IF(H40=P$4,(C40*(1)),IF(H40=P$3,(C40*(-1)),IF(H40=P$2,(C40*(1))))) | G40: =F40*D40 | H40: VENDA | I40: 23.33 | J40: =IF(H40="VENDA",I40*F40*-1,0) | K40: =IF(J40=0,0,J40+G40)
A41: 45894 | B41: CMIG4 | C41: 3 | D41: 10.54 | E41: =IFERROR(VLOOKUP(B41,'Dados B3'!A:G,2,FALSE),"-") | F41: =IF(H41=P$4,(C41*(1)),IF(H41=P$3,(C41*(-1)),IF(H41=P$2,(C41*(1))))) | G41: =F41*D41 | H41: COMPRA | J41: =IF(H41="VENDA",I41*F41*-1,0) | K41: =IF(J41=0,0,J41+G41)
A42: 45894 | B42: CXSE3 | C42: 2 | D42: 15.85 | E42: =IFERROR(VLOOKUP(B42,'Dados B3'!A:G,2,FALSE),"-") | F42: =IF(H42=P$4,(C42*(1)),IF(H42=P$3,(C42*(-1)),IF(H42=P$2,(C42*(1))))) | G42: =F42*D42 | H42: COMPRA | J42: =IF(H42="VENDA",I42*F42*-1,0) | K42: =IF(J42=0,0,J42+G42)
A43: 45894 | B43: AMOB3 | C43: 2 | D43: 14.72 | E43: =IFERROR(VLOOKUP(B43,'Dados B3'!A:G,2,FALSE),"-") | F43: =IF(H43=P$4,(C43*(1)),IF(H43=P$3,(C43*(-1)),IF(H43=P$2,(C43*(1))))) | G43: =F43*D43 | H43: COMPRA | J43: =IF(H43="VENDA",I43*F43*-1,0) | K43: =IF(J43=0,0,J43+G43)
A44: 45894 | B44: ISAE4 | C44: 1 | D44: 23.27 | E44: =IFERROR(VLOOKUP(B44,'Dados B3'!A:G,2,FALSE),"-") | F44: =IF(H44=P$4,(C44*(1)),IF(H44=P$3,(C44*(-1)),IF(H44=P$2,(C44*(1))))) | G44: =F44*D44 | H44: COMPRA | J44: =IF(H44="VENDA",I44*F44*-1,0) | K44: =IF(J44=0,0,J44+G44)
A45: 45916 | B45: BBDC4 | C45: 2 | D45: 12.64 | E45: =IFERROR(VLOOKUP(B45,'Dados B3'!A:G,2,FALSE),"-") | F45: =IF(H45=P$4,(C45*(1)),IF(H45=P$3,(C45*(-1)),IF(H45=P$2,(C45*(1))))) | G45: =F45*D45 | H45: COMPRA | J45: =IF(H45="VENDA",I45*F45*-1,0) | K45: =IF(J45=0,0,J45+G45)
A46: 45916 | B46: ISAE4 | C46: 1 | D46: 23.27 | E46: =IFERROR(VLOOKUP(B46,'Dados B3'!A:G,2,FALSE),"-") | F46: =IF(H46=P$4,(C46*(1)),IF(H46=P$3,(C46*(-1)),IF(H46=P$2,(C46*(1))))) | G46: =F46*D46 | H46: COMPRA | J46: =IF(H46="VENDA",I46*F46*-1,0) | K46: =IF(J46=0,0,J46+G46)
A47: 45916 | B47: BDVD39 | C47: 1 | D47: 47.16 | E47: =IFERROR(VLOOKUP(B47,'Dados B3'!A:G,2,FALSE),"-") | F47: =IF(H47=P$4,(C47*(1)),IF(H47=P$3,(C47*(-1)),IF(H47=P$2,(C47*(1))))) | G47: =F47*D47 | H47: VENDA | I47: 7.59 | J47: =IF(H47="VENDA",I47*F47*-1,0) | K47: =IF(J47=0,0,J47+G47)
A48: 45919 | B48: INLG11 | C48: 1 | D48: 74.96 | E48: =IFERROR(VLOOKUP(B48,'Dados B3'!A:G,2,FALSE),"-") | F48: =IF(H48=P$4,(C48*(1)),IF(H48=P$3,(C48*(-1)),IF(H48=P$2,(C48*(1))))) | G48: =F48*D48 | H48: COMPRA | J48: =IF(H48="VENDA",I48*F48*-1,0) | K48: =IF(J48=0,0,J48+G48)
A49: 45923 | B49: VGRI11 | C49: 10 | D49: 8.64 | E49: =IFERROR(VLOOKUP(B49,'Dados B3'!A:G,2,FALSE),"-") | F49: =IF(H49=P$4,(C49*(1)),IF(H49=P$3,(C49*(-1)),IF(H49=P$2,(C49*(1))))) | G49: =F49*D49 | H49: COMPRA | J49: =IF(H49="VENDA",I49*F49*-1,0) | K49: =IF(J49=0,0,J49+G49)
A50: 45924 | B50: AREA11 | C50: 1 | D50: 100.69 | E50: =IFERROR(VLOOKUP(B50,'Dados B3'!A:G,2,FALSE),"-") | F50: =IF(H50=P$4,(C50*(1)),IF(H50=P$3,(C50*(-1)),IF(H50=P$2,(C50*(1))))) | G50: =F50*D50 | H50: VENDA | I50: 3.48 | J50: =IF(H50="VENDA",I50*F50*-1,0) | K50: =IF(J50=0,0,J50+G50)
A51: 45936 | B51: PETR4 | C51: 4 | D51: 31.06 | E51: =IFERROR(VLOOKUP(B51,'Dados B3'!A:G,2,FALSE),"-") | F51: =IF(H51=P$4,(C51*(1)),IF(H51=P$3,(C51*(-1)),IF(H51=P$2,(C51*(1))))) | G51: =F51*D51 | H51: COMPRA | J51: =IF(H51="VENDA",I51*F51*-1,0) | K51: =IF(J51=0,0,J51+G51)
A52: 45957 | B52: USIM5 | C52: 20 | D52: 4.6 | E52: =IFERROR(VLOOKUP(B52,'Dados B3'!A:G,2,FALSE),"-") | F52: =IF(H52=P$4,(C52*(1)),IF(H52=P$3,(C52*(-1)),IF(H52=P$2,(C52*(1))))) | G52: =F52*D52 | H52: COMPRA | J52: =IF(H52="VENDA",I52*F52*-1,0) | K52: =IF(J52=0,0,J52+G52)
A53: 45957 | B53: BIDB11 | C53: 1 | D53: 77.6 | E53: =IFERROR(VLOOKUP(B53,'Dados B3'!A:G,2,FALSE),"-") | F53: =IF(H53=P$4,(C53*(1)),IF(H53=P$3,(C53*(-1)),IF(H53=P$2,(C53*(1))))) | G53: =F53*D53 | H53: VENDA | I53: 4.67 | J53: =IF(H53="VENDA",I53*F53*-1,0) | K53: =IF(J53=0,0,J53+G53)
A54: 45958 | B54: VINO11 | C54: 1 | D54: 4.96 | E54: =IFERROR(VLOOKUP(B54,'Dados B3'!A:G,2,FALSE),"-") | F54: =IF(H54=P$4,(C54*(1)),IF(H54=P$3,(C54*(-1)),IF(H54=P$2,(C54*(1))))) | G54: =F54*D54 | H54: COMPRA | J54: =IF(H54="VENDA",I54*F54*-1,0) | K54: =IF(J54=0,0,J54+G54)
A55: 45959 | B55: ARRI11 | C55: 10 | D55: 6.56 | E55: =IFERROR(VLOOKUP(B55,'Dados B3'!A:G,2,FALSE),"-") | F55: =IF(H55=P$4,(C55*(1)),IF(H55=P$3,(C55*(-1)),IF(H55=P$2,(C55*(1))))) | G55: =F55*D55 | H55: VENDA | I55: 33.66 | J55: =IF(H55="VENDA",I55*F55*-1,0) | K55: =IF(J55=0,0,J55+G55)
A56: 45959 | B56: RECV3 | C56: 10 | D56: 12.59 | E56: =IFERROR(VLOOKUP(B56,'Dados B3'!A:G,2,FALSE),"-") | F56: =IF(H56=P$4,(C56*(1)),IF(H56=P$3,(C56*(-1)),IF(H56=P$2,(C56*(1))))) | G56: =F56*D56 | H56: VENDA | I56: 9.94 | J56: =IF(H56="VENDA",I56*F56*-1,0) | K56: =IF(J56=0,0,J56+G56)
A57: 45971 | B57: A1VB34 | C57: 1 | D57: 234.86 | E57: =IFERROR(VLOOKUP(B57,'Dados B3'!A:G,2,FALSE),"-") | F57: =IF(H57=P$4,(C57*(1)),IF(H57=P$3,(C57*(-1)),IF(H57=P$2,(C57*(1))))) | G57: =F57*D57 | H57: COMPRA | J57: =IF(H57="VENDA",I57*F57*-1,0) | K57: =IF(J57=0,0,J57+G57)
A58: 45973 | B58: DIVD11 | C58: 1 | D58: 51.04 | E58: =IFERROR(VLOOKUP(B58,'Dados B3'!A:G,2,FALSE),"-") | F58: =IF(H58=P$4,(C58*(1)),IF(H58=P$3,(C58*(-1)),IF(H58=P$2,(C58*(1))))) | G58: =F58*D58 | H58: COMPRA | J58: =IF(H58="VENDA",I58*F58*-1,0) | K58: =IF(J58=0,0,J58+G58)
A59: 45973 | B59: BIDB11 | C59: 2 | D59: 78.67 | E59: =IFERROR(VLOOKUP(B59,'Dados B3'!A:G,2,FALSE),"-") | F59: =IF(H59=P$4,(C59*(1)),IF(H59=P$3,(C59*(-1)),IF(H59=P$2,(C59*(1))))) | G59: =F59*D59 | H59: COMPRA | J59: =IF(H59="VENDA",I59*F59*-1,0) | K59: =IF(J59=0,0,J59+G59)
A60: 45973 | B60: AREA11 | C60: 1 | D60: 100.69 | E60: =IFERROR(VLOOKUP(B60,'Dados B3'!A:G,2,FALSE),"-") | F60: =IF(H60=P$4,(C60*(1)),IF(H60=P$3,(C60*(-1)),IF(H60=P$2,(C60*(1))))) | G60: =F60*D60 | H60: COMPRA | J60: =IF(H60="VENDA",I60*F60*-1,0) | K60: =IF(J60=0,0,J60+G60)
A61: 45978 | B61: LIFE11 | C61: 10 | D61: 8.15 | E61: =IFERROR(VLOOKUP(B61,'Dados B3'!A:G,2,FALSE),"-") | F61: =IF(H61=P$4,(C61*(1)),IF(H61=P$3,(C61*(-1)),IF(H61=P$2,(C61*(1))))) | G61: =F61*D61 | H61: COMPRA | J61: =IF(H61="VENDA",I61*F61*-1,0) | K61: =IF(J61=0,0,J61+G61)
...

Sheet CARTEIRA
A1: CARTEIRA IDEAL | J1: CARTEIRA ATUAL | S1: SUGESTÕES BASEADAS EM FLUXO DE CAIXA
A2: PESO (%) | B2: ATIVO | C2: TIPO | D2: SEGMENTO | E2: QTDE | F2: PREÇO ATUAL | G2: VL TOTAL | H2: D.Y. | J2: TIPO | K2: SEGMENTO | L2: ATIVO | M2: QTDE ATUAL | N2: PREÇO MEDIO | O2: CUSTO TOTAL | P2: PATRIMONIO. ATUAL | Q2: DIFERENÇA | R2: % | S2: COMPRAR | T2: TOTAL APORTE | U2: VENDER
A3: =IFERROR(H3/SUM($H$3:$H$42),0) | B3: AAZQ11 | C3: =IFERROR(VLOOKUP(B3,'Dados B3'!$1:$1048576,2,0),"-") | D3: =IFERROR(VLOOKUP(B3,'Dados B3'!$1:$1048576,6,FALSE),"-") | E3: =IFERROR((G3/F3)*100%,"0") | F3: =IFERROR(VLOOKUP(B3,'Dados B3'!$1:$1048576,4,0),"0,00") | G3: =SUM($P$3:$P$46)*A3 | H3: =IFERROR(_xlfn.NUMBERVALUE(VLOOKUP(B3,'Dados B3'!A:G,7,FALSE),","),0) | J3: =C3 | K3: =D3 | L3: =B3 | M3: =SUMIF(OPERAÇÕES!B:B,L3,OPERAÇÕES!$F:F) | N3: =IF(M3=0,0,SUMIF(OPERAÇÕES!B:B,L3,OPERAÇÕES!$G:G)/M3) | O3: =N3*M3 | P3: =IFERROR(M3*F3,"0,00") | Q3: =P3-O3 | R3: =IFERROR(Q3/O3,"0,00%") | S3: =IFERROR(IF(AND(R3<=SUM($R$3:$R$61))*E3-M3<=0,"0",E3-M3),"0") | T3: =IFERROR(IF(S3*F3<F3*S3,0,S3*F3),"0,00") | U3: =IFERROR(IF(R3<H3,0,IF(M3<E3,0,M3-E3)),"0")
A4: =IFERROR(H4/SUM($H$3:$H$42),0) | B4: AMOB3 | C4: =IFERROR(VLOOKUP(B4,'Dados B3'!$1:$1048576,2,0),"-") | D4: =IFERROR(VLOOKUP(B4,'Dados B3'!$1:$1048576,6,FALSE),"-") | E4: =IFERROR((G4/F4)*100%,"0") | F4: =IFERROR(VLOOKUP(B4,'Dados B3'!$1:$1048576,4,0),"0,00") | G4: =SUM($P$3:$P$46)*A4 | H4: =IFERROR(_xlfn.NUMBERVALUE(VLOOKUP(B4,'Dados B3'!A:G,7,FALSE),","),0) | J4: =C4 | K4: =D4 | L4: =B4 | M4: =SUMIF(OPERAÇÕES!B:B,L4,OPERAÇÕES!$F:F) | N4: =IF(M4=0,0,SUMIF(OPERAÇÕES!B:B,L4,OPERAÇÕES!$G:G)/M4) | O4: =N4*M4 | P4: =IFERROR(M4*F4,"0,00") | Q4: =P4-O4 | R4: =IFERROR(Q4/O4,"0,00%") | S4: =IFERROR(IF(AND(R4<=SUM($R$3:$R$61))*E4-M4<=0,"0",E4-M4),"0") | T4: =IFERROR(IF(S4*F4<F4*S4,0,S4*F4),"0,00") | U4: =IFERROR(IF(R4<H4,0,IF(M4<E4,0,M4-E4)),"0")
A5: =IFERROR(H5/SUM($H$3:$H$42),0) | B5: ARRI11 | C5: =IFERROR(VLOOKUP(B5,'Dados B3'!$1:$1048576,2,0),"-") | D5: =IFERROR(VLOOKUP(B5,'Dados B3'!$1:$1048576,6,FALSE),"-") | E5: =IFERROR((G5/F5)*100%,"0") | F5: =IFERROR(VLOOKUP(B5,'Dados B3'!$1:$1048576,4,0),"0,00") | G5: =SUM($P$3:$P$46)*A5 | H5: =IFERROR(_xlfn.NUMBERVALUE(VLOOKUP(B5,'Dados B3'!A:G,7,FALSE),","),0) | J5: =C5 | K5: =D5 | L5: =B5 | M5: =SUMIF(OPERAÇÕES!B:B,L5,OPERAÇÕES!$F:F) | N5: =IF(M5=0,0,SUMIF(OPERAÇÕES!B:B,L5,OPERAÇÕES!$G:G)/M5) | O5: =N5*M5 | P5: =IFERROR(M5*F5,"0,00") | Q5: =P5-O5 | R5: =IFERROR(Q5/O5,"0,00%") | S5: =IFERROR(IF(AND(R5<=SUM($R$3:$R$61))*E5-M5<=0,"0",E5-M5),"0") | T5: =IFERROR(IF(S5*F5<F5*S5,0,S5*F5),"0,00") | U5: =IFERROR(IF(R5<H5,0,IF(M5<E5,0,M5-E5)),"0")
A6: =IFERROR(H6/SUM($H$3:$H$42),0) | B6: BBAS3 | C6: =IFERROR(VLOOKUP(B6,'Dados B3'!$1:$1048576,2,0),"-") | D6: =IFERROR(VLOOKUP(B6,'Dados B3'!$1:$1048576,6,FALSE),"-") | E6: =IFERROR((G6/F6)*100%,"0") | F6: =IFERROR(VLOOKUP(B6,'Dados B3'!$1:$1048576,4,0),"0,00") | G6: =SUM($P$3:$P$46)*A6 | H6: =IFERROR(_xlfn.NUMBERVALUE(VLOOKUP(B6,'Dados B3'!A:G,7,FALSE),","),0) | J6: =C6 | K6: =D6 | L6: =B6 | M6: =SUMIF(OPERAÇÕES!B:B,L6,OPERAÇÕES!$F:F) | N6: =IF(M6=0,0,SUMIF(OPERAÇÕES!B:B,L6,OPERAÇÕES!$G:G)/M6) | O6: =N6*M6 | P6: =IFERROR(M6*F6,"0,00") | Q6: =P6-O6 | R6: =IFERROR(Q6/O6,"0,00%") | S6: =IFERROR(IF(AND(R6<=SUM($R$3:$R$61))*E6-M6<=0,"0",E6-M6),"0") | T6: =IFERROR(IF(S6*F6<F6*S6,0,S6*F6),"0,00") | U6: =IFERROR(IF(R6<H6,0,IF(M6<E6,0,M6-E6)),"0")
A7: =IFERROR(H7/SUM($H$3:$H$42),0) | B7: BIME11 | C7: =IFERROR(VLOOKUP(B7,'Dados B3'!$1:$1048576,2,0),"-") | D7: =IFERROR(VLOOKUP(B7,'Dados B3'!$1:$1048576,6,FALSE),"-") | E7: =IFERROR((G7/F7)*100%,"0") | F7: =IFERROR(VLOOKUP(B7,'Dados B3'!$1:$1048576,4,0),"0,00") | G7: =SUM($P$3:$P$46)*A7 | H7: =IFERROR(_xlfn.NUMBERVALUE(VLOOKUP(B7,'Dados B3'!A:G,7,FALSE),","),0) | J7: =C7 | K7: =D7 | L7: =B7 | M7: =SUMIF(OPERAÇÕES!B:B,L7,OPERAÇÕES!$F:F) | N7: =IF(M7=0,0,SUMIF(OPERAÇÕES!B:B,L7,OPERAÇÕES!$G:G)/M7) | O7: =N7*M7 | P7: =IFERROR(M7*F7,"0,00") | Q7: =P7-O7 | R7: =IFERROR(Q7/O7,"0,00%") | S7: =IFERROR(IF(AND(R7<=SUM($R$3:$R$61))*E7-M7<=0,"0",E7-M7),"0") | T7: =IFERROR(IF(S7*F7<F7*S7,0,S7*F7),"0,00") | U7: =IFERROR(IF(R7<H7,0,IF(M7<E7,0,M7-E7)),"0")
A8: =IFERROR(H8/SUM($H$3:$H$42),0) | B8: BTHF11 | C8: =IFERROR(VLOOKUP(B8,'Dados B3'!$1:$1048576,2,0),"-") | D8: =IFERROR(VLOOKUP(B8,'Dados B3'!$1:$1048576,6,FALSE),"-") | E8: =IFERROR((G8/F8)*100%,"0") | F8: =IFERROR(VLOOKUP(B8,'Dados B3'!$1:$1048576,4,0),"0,00") | G8: =SUM($P$3:$P$46)*A8 | H8: =IFERROR(_xlfn.NUMBERVALUE(VLOOKUP(B8,'Dados B3'!A:G,7,FALSE),","),0) | J8: =C8 | K8: =D8 | L8: =B8 | M8: =SUMIF(OPERAÇÕES!B:B,L8,OPERAÇÕES!$F:F) | N8: =IF(M8=0,0,SUMIF(OPERAÇÕES!B:B,L8,OPERAÇÕES!$G:G)/M8) | O8: =N8*M8 | P8: =IFERROR(M8*F8,"0,00") | Q8: =P8-O8 | R8: =IFERROR(Q8/O8,"0,00%") | S8: =IFERROR(IF(AND(R8<=SUM($R$3:$R$61))*E8-M8<=0,"0",E8-M8),"0") | T8: =IFERROR(IF(S8*F8<F8*S8,0,S8*F8),"0,00") | U8: =IFERROR(IF(R8<H8,0,IF(M8<E8,0,M8-E8)),"0")
A9: =IFERROR(H9/SUM($H$3:$H$42),0) | B9: CMIG4 | C9: =IFERROR(VLOOKUP(B9,'Dados B3'!$1:$1048576,2,0),"-") | D9: =IFERROR(VLOOKUP(B9,'Dados B3'!$1:$1048576,6,FALSE),"-") | E9: =IFERROR((G9/F9)*100%,"0") | F9: =IFERROR(VLOOKUP(B9,'Dados B3'!$1:$1048576,4,0),"0,00") | G9: =SUM($P$3:$P$46)*A9 | H9: =IFERROR(_xlfn.NUMBERVALUE(VLOOKUP(B9,'Dados B3'!A:G,7,FALSE),","),0) | J9: =C9 | K9: =D9 | L9: =B9 | M9: =SUMIF(OPERAÇÕES!B:B,L9,OPERAÇÕES!$F:F) | N9: =IF(M9=0,0,SUMIF(OPERAÇÕES!B:B,L9,OPERAÇÕES!$G:G)/M9) | O9: =N9*M9 | P9: =IFERROR(M9*F9,"0,00") | Q9: =P9-O9 | R9: =IFERROR(Q9/O9,"0,00%") | S9: =IFERROR(IF(AND(R9<=SUM($R$3:$R$61))*E9-M9<=0,"0",E9-M9),"0") | T9: =IFERROR(IF(S9*F9<F9*S9,0,S9*F9),"0,00") | U9: =IFERROR(IF(R9<H9,0,IF(M9<E9,0,M9-E9)),"0")
A10: =IFERROR(H10/SUM($H$3:$H$42),0) | B10: CPSH11 | C10: =IFERROR(VLOOKUP(B10,'Dados B3'!$1:$1048576,2,0),"-") | D10: =IFERROR(VLOOKUP(B10,'Dados B3'!$1:$1048576,6,FALSE),"-") | E10: =IFERROR((G10/F10)*100%,"0") | F10: =IFERROR(VLOOKUP(B10,'Dados B3'!$1:$1048576,4,0),"0,00") | G10: =SUM($P$3:$P$46)*A10 | H10: =IFERROR(_xlfn.NUMBERVALUE(VLOOKUP(B10,'Dados B3'!A:G,7,FALSE),","),0) | J10: =C10 | K10: =D10 | L10: =B10 | M10: =SUMIF(OPERAÇÕES!B:B,L10,OPERAÇÕES!$F:F) | N10: =IF(M10=0,0,SUMIF(OPERAÇÕES!B:B,L10,OPERAÇÕES!$G:G)/M10) | O10: =N10*M10 | P10: =IFERROR(M10*F10,"0,00") | Q10: =P10-O10 | R10: =IFERROR(Q10/O10,"0,00%") | S10: =IFERROR(IF(AND(R10<=SUM($R$3:$R$61))*E10-M10<=0,"0",E10-M10),"0") | T10: =IFERROR(IF(S10*F10<F10*S10,0,S10*F10),"0,00") | U10: =IFERROR(IF(R10<H10,0,IF(M10<E10,0,M10-E10)),"0")
A11: =IFERROR(H11/SUM($H$3:$H$42),0) | B11: CPTS11 | C11: =IFERROR(VLOOKUP(B11,'Dados B3'!$1:$1048576,2,0),"-") | D11: =IFERROR(VLOOKUP(B11,'Dados B3'!$1:$1048576,6,FALSE),"-") | E11: =IFERROR((G11/F11)*100%,"0") | F11: =IFERROR(VLOOKUP(B11,'Dados B3'!$1:$1048576,4,0),"0,00") | G11: =SUM($P$3:$P$46)*A11 | H11: =IFERROR(_xlfn.NUMBERVALUE(VLOOKUP(B11,'Dados B3'!A:G,7,FALSE),","),0) | J11: =C11 | K11: =D11 | L11: =B11 | M11: =SUMIF(OPERAÇÕES!B:B,L11,OPERAÇÕES!$F:F) | N11: =IF(M11=0,0,SUMIF(OPERAÇÕES!B:B,L11,OPERAÇÕES!$G:G)/M11) | O11: =N11*M11 | P11: =IFERROR(M11*F11,"0,00") | Q11: =P11-O11 | R11: =IFERROR(Q11/O11,"0,00%") | S11: =IFERROR(IF(AND(R11<=SUM($R$3:$R$61))*E11-M11<=0,"0",E11-M11),"0") | T11: =IFERROR(IF(S11*F11<F11*S11,0,S11*F11),"0,00") | U11: =IFERROR(IF(R11<H11,0,IF(M11<E11,0,M11-E11)),"0")
A12: =IFERROR(H12/SUM($H$3:$H$42),0) | B12: CURY3 | C12: =IFERROR(VLOOKUP(B12,'Dados B3'!$1:$1048576,2,0),"-") | D12: =IFERROR(VLOOKUP(B12,'Dados B3'!$1:$1048576,6,FALSE),"-") | E12: =IFERROR((G12/F12)*100%,"0") | F12: =IFERROR(VLOOKUP(B12,'Dados B3'!$1:$1048576,4,0),"0,00") | G12: =SUM($P$3:$P$46)*A12 | H12: =IFERROR(_xlfn.NUMBERVALUE(VLOOKUP(B12,'Dados B3'!A:G,7,FALSE),","),0) | J12: =C12 | K12: =D12 | L12: =B12 | M12: =SUMIF(OPERAÇÕES!B:B,L12,OPERAÇÕES!$F:F) | N12: =IF(M12=0,0,SUMIF(OPERAÇÕES!B:B,L12,OPERAÇÕES!$G:G)/M12) | O12: =N12*M12 | P12: =IFERROR(M12*F12,"0,00") | Q12: =P12-O12 | R12: =IFERROR(Q12/O12,"0,00%") | S12: =IFERROR(IF(AND(R12<=SUM($R$3:$R$61))*E12-M12<=0,"0",E12-M12),"0") | T12: =IFERROR(IF(S12*F12<F12*S12,0,S12*F12),"0,00") | U12: =IFERROR(IF(R12<H12,0,IF(M12<E12,0,M12-E12)),"0")
A13: =IFERROR(H13/SUM($H$3:$H$42),0) | B13: CXSE3 | C13: =IFERROR(VLOOKUP(B13,'Dados B3'!$1:$1048576,2,0),"-") | D13: =IFERROR(VLOOKUP(B13,'Dados B3'!$1:$1048576,6,FALSE),"-") | E13: =IFERROR((G13/F13)*100%,"0") | F13: =IFERROR(VLOOKUP(B13,'Dados B3'!$1:$1048576,4,0),"0,00") | G13: =SUM($P$3:$P$46)*A13 | H13: =IFERROR(_xlfn.NUMBERVALUE(VLOOKUP(B13,'Dados B3'!A:G,7,FALSE),","),0) | J13: =C13 | K13: =D13 | L13: =B13 | M13: =SUMIF(OPERAÇÕES!B:B,L13,OPERAÇÕES!$F:F) | N13: =IF(M13=0,0,SUMIF(OPERAÇÕES!B:B,L13,OPERAÇÕES!$G:G)/M13) | O13: =N13*M13 | P13: =IFERROR(M13*F13,"0,00") | Q13: =P13-O13 | R13: =IFERROR(Q13/O13,"0,00%") | S13: =IFERROR(IF(AND(R13<=SUM($R$3:$R$61))*E13-M13<=0,"0",E13-M13),"0") | T13: =IFERROR(IF(S13*F13<F13*S13,0,S13*F13),"0,00") | U13: =IFERROR(IF(R13<H13,0,IF(M13<E13,0,M13-E13)),"0")
A14: =IFERROR(H14/SUM($H$3:$H$42),0) | B14: CYRE3 | C14: =IFERROR(VLOOKUP(B14,'Dados B3'!$1:$1048576,2,0),"-") | D14: =IFERROR(VLOOKUP(B14,'Dados B3'!$1:$1048576,6,FALSE),"-") | E14: =IFERROR((G14/F14)*100%,"0") | F14: =IFERROR(VLOOKUP(B14,'Dados B3'!$1:$1048576,4,0),"0,00") | G14: =SUM($P$3:$P$46)*A14 | H14: =IFERROR(_xlfn.NUMBERVALUE(VLOOKUP(B14,'Dados B3'!A:G,7,FALSE),","),0) | J14: =C14 | K14: =D14 | L14: =B14 | M14: =SUMIF(OPERAÇÕES!B:B,L14,OPERAÇÕES!$F:F) | N14: =IF(M14=0,0,SUMIF(OPERAÇÕES!B:B,L14,OPERAÇÕES!$G:G)/M14) | O14: =N14*M14 | P14: =IFERROR(M14*F14,"0,00") | Q14: =P14-O14 | R14: =IFERROR(Q14/O14,"0,00%") | S14: =IFERROR(IF(AND(R14<=SUM($R$3:$R$61))*E14-M14<=0,"0",E14-M14),"0") | T14: =IFERROR(IF(S14*F14<F14*S14,0,S14*F14),"0,00") | U14: =IFERROR(IF(R14<H14,0,IF(M14<E14,0,M14-E14)),"0")
... A37: =IFERROR(H37/SUM($H$3:$H$42),0) | B37: XPML11 | C37: =IFERROR(VLOOKUP(B37,'Dados B3'!$1:$1048576,2,0),"-") | D37: =IFERROR(VLOOKUP(B37,'Dados B3'!$1:$1048576,6,FALSE),"-") | E37: =IFERROR((G37/F37)*100%,"0") | F37: =IFERROR(VLOOKUP(B37,'Dados B3'!$1:$1048576,4,0),"0,00") | G37: =SUM($P$3:$P$46)*A37 | H37: =IFERROR(_xlfn.NUMBERVALUE(VLOOKUP(B37,'Dados B3'!A:G,7,FALSE),","),0) | J37: =C37 | K37: =D37 | L37: =B37 | M37: =SUMIF(OPERAÇÕES!B:B,L37,OPERAÇÕES!$F:F) | N37: =IF(M37=0,0,SUMIF(OPERAÇÕES!B:B,L37,OPERAÇÕES!$G:G)/M37) | O37: =N37*M37 | P37: =IFERROR(M37*F37,"0,00") | Q37: =P37-O37 | R37: =IFERROR(Q37/O37,"0,00%") | S37: =IFERROR(IF(AND(R37<=SUM($R$3:$R$61))*E37-M37<=0,"0",E37-M37),"0") | T37: =IFERROR(IF(S37*F37<F37*S37,0,S37*F37),"0,00") | U37: =IFERROR(IF(R37<H37,0,IF(M37<E37,0,M37-E37)),"0")
A38: =IFERROR(H38/SUM($H$3:$H$42),0) | C38: =IFERROR(VLOOKUP(B38,'Dados B3'!$1:$1048576,2,0),"-") | D38: =IFERROR(VLOOKUP(B38,'Dados B3'!$1:$1048576,6,FALSE),"-") | E38: =IFERROR((G38/F38)*100%,"0") | F38: =IFERROR(VLOOKUP(B38,'Dados B3'!$1:$1048576,4,0),"0,00") | G38: =SUM($P$3:$P$46)*A38 | H38: =IFERROR(_xlfn.NUMBERVALUE(VLOOKUP(B38,'Dados B3'!A:G,7,FALSE),","),0) | J38: =C38 | K38: =D38 | L38: =B38 | M38: =SUMIF(OPERAÇÕES!B:B,L38,OPERAÇÕES!$F:F) | N38: =IF(M38=0,0,SUMIF(OPERAÇÕES!B:B,L38,OPERAÇÕES!$G:G)/M38) | O38: =N38*M38 | P38: =IFERROR(M38*F38,"0,00") | Q38: =P38-O38 | R38: =IFERROR(Q38/O38,"0,00%") | S38: =IFERROR(IF(AND(R38<=SUM($R$3:$R$61))*E38-M38<=0,"0",E38-M38),"0") | T38: =IFERROR(IF(S38*F38<F38*S38,0,S38*F38),"0,00") | U38: =IFERROR(IF(R38<H38,0,IF(M38<E38,0,M38-E38)),"0")
A39: =IFERROR(H39/SUM($H$3:$H$42),0) | C39: =IFERROR(VLOOKUP(B39,'Dados B3'!$1:$1048576,2,0),"-") | D39: =IFERROR(VLOOKUP(B39,'Dados B3'!$1:$1048576,6,FALSE),"-") | E39: =IFERROR((G39/F39)*100%,"0") | F39: =IFERROR(VLOOKUP(B39,'Dados B3'!$1:$1048576,4,0),"0,00") | G39: =SUM($P$3:$P$46)*A39 | H39: =IFERROR(_xlfn.NUMBERVALUE(VLOOKUP(B39,'Dados B3'!A:G,7,FALSE),","),0) | J39: =C39 | K39: =D39 | L39: =B39 | M39: =SUMIF(OPERAÇÕES!B:B,L39,OPERAÇÕES!$F:F) | N39: =IF(M39=0,0,SUMIF(OPERAÇÕES!B:B,L39,OPERAÇÕES!$G:G)/M39) | O39: =N39*M39 | P39: =IFERROR(M39*F39,"0,00") | Q39: =P39-O39 | R39: =IFERROR(Q39/O39,"0,00%") | S39: =IFERROR(IF(AND(R39<=SUM($R$3:$R$61))*E39-M39<=0,"0",E39-M39),"0") | T39: =IFERROR(IF(S39*F39<F39*S39,0,S39*F39),"0,00") | U39: =IFERROR(IF(R39<H39,0,IF(M39<E39,0,M39-E39)),"0")
A40: =IFERROR(H40/SUM($H$3:$H$42),0) | C40: =IFERROR(VLOOKUP(B40,'Dados B3'!$1:$1048576,2,0),"-") | D40: =IFERROR(VLOOKUP(B40,'Dados B3'!$1:$1048576,6,FALSE),"-") | E40: =IFERROR((G40/F40)*100%,"0") | F40: =IFERROR(VLOOKUP(B40,'Dados B3'!$1:$1048576,4,0),"0,00") | G40: =SUM($P$3:$P$46)*A40 | H40: =IFERROR(_xlfn.NUMBERVALUE(VLOOKUP(B40,'Dados B3'!A:G,7,FALSE),","),0) | J40: =C40 | K40: =D40 | L40: =B40 | M40: =SUMIF(OPERAÇÕES!B:B,L40,OPERAÇÕES!$F:F) | N40: =IF(M40=0,0,SUMIF(OPERAÇÕES!B:B,L40,OPERAÇÕES!$G:G)/M40) | O40: =N40*M40 | P40: =IFERROR(M40*F40,"0,00") | Q40: =P40-O40 | R40: =IFERROR(Q40/O40,"0,00%") | S40: =IFERROR(IF(AND(R40<=SUM($R$3:$R$61))*E40-M40<=0,"0",E40-M40),"0") | T40: =IFERROR(IF(S40*F40<F40*S40,0,S40*F40),"0,00") | U40: =IFERROR(IF(R40<H40,0,IF(M40<E40,0,M40-E40)),"0")
A41: =IFERROR(H41/SUM($H$3:$H$42),0) | C41: =IFERROR(VLOOKUP(B41,'Dados B3'!$1:$1048576,2,0),"-") | D41: =IFERROR(VLOOKUP(B41,'Dados B3'!$1:$1048576,6,FALSE),"-") | E41: =IFERROR((G41/F41)*100%,"0") | F41: =IFERROR(VLOOKUP(B41,'Dados B3'!$1:$1048576,4,0),"0,00") | G41: =SUM($P$3:$P$46)*A41 | H41: =IFERROR(_xlfn.NUMBERVALUE(VLOOKUP(B41,'Dados B3'!A:G,7,FALSE),","),0) | J41: =C41 | K41: =D41 | L41: =B41 | M41: =SUMIF(OPERAÇÕES!B:B,L41,OPERAÇÕES!$F:F) | N41: =IF(M41=0,0,SUMIF(OPERAÇÕES!B:B,L41,OPERAÇÕES!$G:G)/M41) | O41: =N41*M41 | P41: =IFERROR(M41*F41,"0,00") | Q41: =P41-O41 | R41: =IFERROR(Q41/O41,"0,00%") | S41: =IFERROR(IF(AND(R41<=SUM($R$3:$R$61))*E41-M41<=0,"0",E41-M41),"0") | T41: =IFERROR(IF(S41*F41<F41*S41,0,S41*F41),"0,00") | U41: =IFERROR(IF(R41<H41,0,IF(M41<E41,0,M41-E41)),"0")
A42: =IFERROR(H42/SUM($H$3:$H$42),0) | C42: =IFERROR(VLOOKUP(B42,'Dados B3'!$1:$1048576,2,0),"-") | D42: =IFERROR(VLOOKUP(B42,'Dados B3'!$1:$1048576,6,FALSE),"-") | E42: =IFERROR((G42/F42)*100%,"0") | F42: =IFERROR(VLOOKUP(B42,'Dados B3'!$1:$1048576,4,0),"0,00") | G42: =SUM($P$3:$P$46)*A42 | H42: =IFERROR(_xlfn.NUMBERVALUE(VLOOKUP(B42,'Dados B3'!A:G,7,FALSE),","),0) | J42: =C42 | K42: =D42 | L42: =B42 | M42: =SUMIF(OPERAÇÕES!B:B,L42,OPERAÇÕES!$F:F) | N42: =IF(M42=0,0,SUMIF(OPERAÇÕES!B:B,L42,OPERAÇÕES!$G:G)/M42) | O42: =N42*M42 | P42: =IFERROR(M42*F42,"0,00") | Q42: =P42-O42 | R42: =IFERROR(Q42/O42,"0,00%") | S42: =IFERROR(IF(AND(R42<=SUM($R$3:$R$61))*E42-M42<=0,"0",E42-M42),"0") | T42: =IFERROR(IF(S42*F42<F42*S42,0,S42*F42),"0,00") | U42: =IFERROR(IF(R42<H42,0,IF(M42<E42,0,M42-E42)),"0")
A43: =IFERROR(H43/SUM($H$3:$H$42),0) | C43: =IFERROR(VLOOKUP(B43,'Dados B3'!$1:$1048576,2,0),"-") | D43: =IFERROR(VLOOKUP(B43,'Dados B3'!$1:$1048576,6,FALSE),"-") | E43: =IFERROR((G43/F43)*100%,"0") | F43: =IFERROR(VLOOKUP(B43,'Dados B3'!$1:$1048576,4,0),"0,00") | G43: =SUM($P$3:$P$46)*A43 | H43: =IFERROR(_xlfn.NUMBERVALUE(VLOOKUP(B43,'Dados B3'!A:G,7,FALSE),","),0) | J43: =C43 | K43: =D43 | L43: =B43 | M43: =SUMIF(OPERAÇÕES!B:B,L43,OPERAÇÕES!$F:F) | N43: =IF(M43=0,0,SUMIF(OPERAÇÕES!B:B,L43,OPERAÇÕES!$G:G)/M43) | O43: =N43*M43 | P43: =IFERROR(M43*F43,"0,00") | Q43: =P43-O43 | R43: =IFERROR(Q43/O43,"0,00%") | S43: =IFERROR(IF(AND(R43<=SUM($R$3:$R$61))*E43-M43<=0,"0",E43-M43),"0") | T43: =IFERROR(IF(S43*F43<F43*S43,0,S43*F43),"0,00") | U43: =IFERROR(IF(R43<H43,0,IF(M43<E43,0,M43-E43)),"0")
A44: =IFERROR(H44/SUM($H$3:$H$42),0) | C44: =IFERROR(VLOOKUP(B44,'Dados B3'!$1:$1048576,2,0),"-") | D44: =IFERROR(VLOOKUP(B44,'Dados B3'!$1:$1048576,6,FALSE),"-") | E44: =IFERROR((G44/F44)*100%,"0") | F44: =IFERROR(VLOOKUP(B44,'Dados B3'!$1:$1048576,4,0),"0,00") | G44: =SUM($P$3:$P$46)*A44 | H44: =IFERROR(_xlfn.NUMBERVALUE(VLOOKUP(B44,'Dados B3'!A:G,7,FALSE),","),0) | J44: =C44 | K44: =D44 | L44: =B44 | M44: =SUMIF(OPERAÇÕES!B:B,L44,OPERAÇÕES!$F:F) | N44: =IF(M44=0,0,SUMIF(OPERAÇÕES!B:B,L44,OPERAÇÕES!$G:G)/M44) | O44: =N44*M44 | P44: =IFERROR(M44*F44,"0,00") | Q44: =P44-O44 | R44: =IFERROR(Q44/O44,"0,00%") | S44: =IFERROR(IF(AND(R44<=SUM($R$3:$R$61))*E44-M44<=0,"0",E44-M44),"0") | T44: =IFERROR(IF(S44*F44<F44*S44,0,S44*F44),"0,00") | U44: =IFERROR(IF(R44<H44,0,IF(M44<E44,0,M44-E44)),"0")
A45: =IFERROR(H45/SUM($H$3:$H$42),0) | C45: =IFERROR(VLOOKUP(B45,'Dados B3'!$1:$1048576,2,0),"-") | D45: =IFERROR(VLOOKUP(B45,'Dados B3'!$1:$1048576,6,FALSE),"-") | E45: =IFERROR((G45/F45)*100%,"0") | F45: =IFERROR(VLOOKUP(B45,'Dados B3'!$1:$1048576,4,0),"0,00") | G45: =SUM($P$3:$P$46)*A45 | H45: =IFERROR(_xlfn.NUMBERVALUE(VLOOKUP(B45,'Dados B3'!A:G,7,FALSE),","),0) | J45: =C45 | K45: =D45 | L45: =B45 | M45: =SUMIF(OPERAÇÕES!B:B,L45,OPERAÇÕES!$F:F) | N45: =IF(M45=0,0,SUMIF(OPERAÇÕES!B:B,L45,OPERAÇÕES!$G:G)/M45) | O45: =N45*M45 | P45: =IFERROR(M45*F45,"0,00") | Q45: =P45-O45 | R45: =IFERROR(Q45/O45,"0,00%") | S45: =IFERROR(IF(AND(R45<=SUM($R$3:$R$61))*E45-M45<=0,"0",E45-M45),"0") | T45: =IFERROR(IF(S45*F45<F45*S45,0,S45*F45),"0,00") | U45: =IFERROR(IF(R45<H45,0,IF(M45<E45,0,M45-E45)),"0")
A46: =IFERROR(H46/SUM($H$3:$H$42),0) | C46: =IFERROR(VLOOKUP(B46,'Dados B3'!$1:$1048576,2,0),"-") | D46: =IFERROR(VLOOKUP(B46,'Dados B3'!$1:$1048576,6,FALSE),"-") | E46: =IFERROR((G46/F46)*100%,"0") | F46: =IFERROR(VLOOKUP(B46,'Dados B3'!$1:$1048576,4,0),"0,00") | G46: =SUM($P$3:$P$46)*A46 | H46: =IFERROR(_xlfn.NUMBERVALUE(VLOOKUP(B46,'Dados B3'!A:G,7,FALSE),","),0) | J46: =C46 | K46: =D46 | L46: =B46 | M46: =SUMIF(OPERAÇÕES!B:B,L46,OPERAÇÕES!$F:F) | N46: =IF(M46=0,0,SUMIF(OPERAÇÕES!B:B,L46,OPERAÇÕES!$G:G)/M46) | O46: =N46*M46 | P46: =IFERROR(M46*F46,"0,00") | Q46: =P46-O46 | R46: =IFERROR(Q46/O46,"0,00%") | S46: =IFERROR(IF(AND(R46<=SUM($R$3:$R$61))*E46-M46<=0,"0",E46-M46),"0") | T46: =IFERROR(IF(S46*F46<F46*S46,0,S46*F46),"0,00") | U46: =IFERROR(IF(R46<H46,0,IF(M46<E46,0,M46-E46)),"0")
A47: =IFERROR(H47/SUM($H$3:$H$42),0) | C47: =IFERROR(VLOOKUP(B47,'Dados B3'!$1:$1048576,2,0),"-") | D47: =IFERROR(VLOOKUP(B47,'Dados B3'!$1:$1048576,6,FALSE),"-") | E47: =IFERROR((G47/F47)*100%,"0") | F47: =IFERROR(VLOOKUP(B47,'Dados B3'!$1:$1048576,4,0),"0,00") | G47: =SUM($P$3:$P$46)*A47 | H47: =IFERROR(_xlfn.NUMBERVALUE(VLOOKUP(B47,'Dados B3'!A:G,7,FALSE),","),0) | J47: =C47 | K47: =D47 | L47: =B47 | M47: =SUMIF(OPERAÇÕES!B:B,L47,OPERAÇÕES!$F:F) | N47: =IF(M47=0,0,SUMIF(OPERAÇÕES!B:B,L47,OPERAÇÕES!$G:G)/M47) | O47: =N47*M47 | P47: =IFERROR(M47*F47,"0,00") | Q47: =P47-O47 | R47: =IFERROR(Q47/O47,"0,00%") | S47: =IFERROR(IF(AND(R47<=SUM($R$3:$R$61))*E47-M47<=0,"0",E47-M47),"0") | T47: =IFERROR(IF(S47*F47<F47*S47,0,S47*F47),"0,00") | U47: =IFERROR(IF(R47<H47,0,IF(M47<E47,0,M47-E47)),"0")
A48: =IFERROR(H48/SUM($H$3:$H$42),0) | C48: =IFERROR(VLOOKUP(B48,'Dados B3'!$1:$1048576,2,0),"-") | D48: =IFERROR(VLOOKUP(B48,'Dados B3'!$1:$1048576,6,FALSE),"-") | E48: =IFERROR((G48/F48)*100%,"0") | F48: =IFERROR(VLOOKUP(B48,'Dados B3'!$1:$1048576,4,0),"0,00") | G48: =SUM($P$3:$P$46)*A48 | H48: =IFERROR(_xlfn.NUMBERVALUE(VLOOKUP(B48,'Dados B3'!A:G,7,FALSE),","),0) | J48: =C48 | K48: =D48 | L48: =B48 | M48: =SUMIF(OPERAÇÕES!B:B,L48,OPERAÇÕES!$F:F) | N48: =IF(M48=0,0,SUMIF(OPERAÇÕES!B:B,L48,OPERAÇÕES!$G:G)/M48) | O48: =N48*M48 | P48: =IFERROR(M48*F48,"0,00") | Q48: =P48-O48 | R48: =IFERROR(Q48/O48,"0,00%") | S48: =IFERROR(IF(AND(R48<=SUM($R$3:$R$61))*E48-M48<=0,"0",E48-M48),"0") | T48: =IFERROR(IF(S48*F48<F48*S48,0,S48*F48),"0,00") | U48: =IFERROR(IF(R48<H48,0,IF(M48<E48,0,M48-E48)),"0")
A49: =IFERROR(H49/SUM($H$3:$H$42),0) | C49: =IFERROR(VLOOKUP(B49,'Dados B3'!$1:$1048576,2,0),"-") | D49: =IFERROR(VLOOKUP(B49,'Dados B3'!$1:$1048576,6,FALSE),"-") | E49: =IFERROR((G49/F49)*100%,"0") | F49: =IFERROR(VLOOKUP(B49,'Dados B3'!$1:$1048576,4,0),"0,00") | G49: =SUM($P$3:$P$46)*A49 | H49: =IFERROR(_xlfn.NUMBERVALUE(VLOOKUP(B49,'Dados B3'!A:G,7,FALSE),","),0) | J49: =C49 | K49: =D49 | L49: =B49 | M49: =SUMIF(OPERAÇÕES!B:B,L49,OPERAÇÕES!$F:F) | N49: =IF(M49=0,0,SUMIF(OPERAÇÕES!B:B,L49,OPERAÇÕES!$G:G)/M49) | O49: =N49*M49 | P49: =IFERROR(M49*F49,"0,00") | Q49: =P49-O49 | R49: =IFERROR(Q49/O49,"0,00%") | S49: =IFERROR(IF(AND(R49<=SUM($R$3:$R$61))*E49-M49<=0,"0",E49-M49),"0") | T49: =IFERROR(IF(S49*F49<F49*S49,0,S49*F49),"0,00") | U49: =IFERROR(IF(R49<H49,0,IF(M49<E49,0,M49-E49)),"0")
... A61: =IFERROR(H61/SUM($H$3:$H$42),0) | C61: =IFERROR(VLOOKUP(B61,'Dados B3'!$1:$1048576,2,0),"-") | D61: =IFERROR(VLOOKUP(B61,'Dados B3'!$1:$1048576,6,FALSE),"-") | E61: =IFERROR((G61/F61)*100%,"0") | F61: =IFERROR(VLOOKUP(B61,'Dados B3'!$1:$1048576,4,0),"0,00") | G61: =SUM($P$3:$P$46)*A61 | H61: =IFERROR(_xlfn.NUMBERVALUE(VLOOKUP(B61,'Dados B3'!A:G,7,FALSE),","),0) | J61: =C61 | K61: =D61 | L61: =B61 | M61: =SUMIF(OPERAÇÕES!B:B,L61,OPERAÇÕES!$F:F) | N61: =IF(M61=0,0,SUMIF(OPERAÇÕES!B:B,L61,OPERAÇÕES!$G:G)/M61) | O61: =N61*M61 | P61: =IFERROR(M61*F61,"0,00") | Q61: =P61-O61 | R61: =IFERROR(Q61/O61,"0,00%") | S61: =IFERROR(IF(AND(R61<=SUM($R$3:$R$61))*E61-M61<=0,"0",E61-M61),"0") | T61: =IFERROR(IF(S61*F61<F61*S61,0,S61*F61),"0,00") | U61: =IFERROR(IF(R61<H61,0,IF(M61<E61,0,M61-E61)),"0")

Sheet DASHBOARD
A1: =CARTEIRA!J2 | B1: =CARTEIRA!K2 | C1: =CARTEIRA!L2 | D1: =CARTEIRA!M2 | E1: =CARTEIRA!N2 | F1: =CARTEIRA!O2 | G1: =CARTEIRA!P2 | H1: =CARTEIRA!Q2 | I1: =CARTEIRA!R2 | N1: Rótulos de Linha | Q1: Rótulos de Linha | T1: Rótulos de Linha
A2: =IF(CARTEIRA!J3=0,"",CARTEIRA!J3) | B2: =IF(CARTEIRA!K3=0,"",CARTEIRA!K3) | C2: =IF(CARTEIRA!L3=0,"",CARTEIRA!L3) | D2: =IF(CARTEIRA!M3=0,"",CARTEIRA!M3) | E2: =IF(CARTEIRA!N3=0,"",CARTEIRA!N3) | F2: =IF(CARTEIRA!O3=0,"",CARTEIRA!O3) | G2: =IF(CARTEIRA!P3=0,"",CARTEIRA!P3) | H2: =IF(CARTEIRA!Q3=0,"",CARTEIRA!Q3) | I2: =IF(CARTEIRA!R3=0,"",CARTEIRA!R3) | N2: FII | Q2: CPTS11 | T2: -
A3: =IF(CARTEIRA!J4=0,"",CARTEIRA!J4) | B3: =IF(CARTEIRA!K4=0,"",CARTEIRA!K4) | C3: =IF(CARTEIRA!L4=0,"",CARTEIRA!L4) | D3: =IF(CARTEIRA!M4=0,"",CARTEIRA!M4) | E3: =IF(CARTEIRA!N4=0,"",CARTEIRA!N4) | F3: =IF(CARTEIRA!O4=0,"",CARTEIRA!O4) | G3: =IF(CARTEIRA!P4=0,"",CARTEIRA!P4) | H3: =IF(CARTEIRA!Q4=0,"",CARTEIRA!Q4) | I3: =IF(CARTEIRA!R4=0,"",CARTEIRA!R4) | N3: Ação | Q3: VINO11 | T3: Total Geral
A4: =IF(CARTEIRA!J5=0,"",CARTEIRA!J5) | B4: =IF(CARTEIRA!K5=0,"",CARTEIRA!K5) | C4: =IF(CARTEIRA!L5=0,"",CARTEIRA!L5) | D4: =IF(CARTEIRA!M5=0,"",CARTEIRA!M5) | E4: =IF(CARTEIRA!N5=0,"",CARTEIRA!N5) | F4: =IF(CARTEIRA!O5=0,"",CARTEIRA!O5) | G4: =IF(CARTEIRA!P5=0,"",CARTEIRA!P5) | H4: =IF(CARTEIRA!Q5=0,"",CARTEIRA!Q5) | I4: =IF(CARTEIRA!R5=0,"",CARTEIRA!R5) | N4: - | Q4: CPSH11
A5: =IF(CARTEIRA!J6=0,"",CARTEIRA!J6) | B5: =IF(CARTEIRA!K6=0,"",CARTEIRA!K6) | C5: =IF(CARTEIRA!L6=0,"",CARTEIRA!L6) | D5: =IF(CARTEIRA!M6=0,"",CARTEIRA!M6) | E5: =IF(CARTEIRA!N6=0,"",CARTEIRA!N6) | F5: =IF(CARTEIRA!O6=0,"",CARTEIRA!O6) | G5: =IF(CARTEIRA!P6=0,"",CARTEIRA!P6) | H5: =IF(CARTEIRA!Q6=0,"",CARTEIRA!Q6) | I5: =IF(CARTEIRA!R6=0,"",CARTEIRA!R6) | N5: Total Geral | Q5: GARE11
A6: =IF(CARTEIRA!J7=0,"",CARTEIRA!J7) | B6: =IF(CARTEIRA!K7=0,"",CARTEIRA!K7) | C6: =IF(CARTEIRA!L7=0,"",CARTEIRA!L7) | D6: =IF(CARTEIRA!M7=0,"",CARTEIRA!M7) | E6: =IF(CARTEIRA!N7=0,"",CARTEIRA!N7) | F6: =IF(CARTEIRA!O7=0,"",CARTEIRA!O7) | G6: =IF(CARTEIRA!P7=0,"",CARTEIRA!P7) | H6: =IF(CARTEIRA!Q7=0,"",CARTEIRA!Q7) | I6: =IF(CARTEIRA!R7=0,"",CARTEIRA!R7) | Q6: AAZQ11
A7: =IF(CARTEIRA!J8=0,"",CARTEIRA!J8) | B7: =IF(CARTEIRA!K8=0,"",CARTEIRA!K8) | C7: =IF(CARTEIRA!L8=0,"",CARTEIRA!L8) | D7: =IF(CARTEIRA!M8=0,"",CARTEIRA!M8) | E7: =IF(CARTEIRA!N8=0,"",CARTEIRA!N8) | F7: =IF(CARTEIRA!O8=0,"",CARTEIRA!O8) | G7: =IF(CARTEIRA!P8=0,"",CARTEIRA!P8) | H7: =IF(CARTEIRA!Q8=0,"",CARTEIRA!Q8) | I7: =IF(CARTEIRA!R8=0,"",CARTEIRA!R8) | Q7: ARRI11
A8: =IF(CARTEIRA!J9=0,"",CARTEIRA!J9) | B8: =IF(CARTEIRA!K9=0,"",CARTEIRA!K9) | C8: =IF(CARTEIRA!L9=0,"",CARTEIRA!L9) | D8: =IF(CARTEIRA!M9=0,"",CARTEIRA!M9) | E8: =IF(CARTEIRA!N9=0,"",CARTEIRA!N9) | F8: =IF(CARTEIRA!O9=0,"",CARTEIRA!O9) | G8: =IF(CARTEIRA!P9=0,"",CARTEIRA!P9) | H8: =IF(CARTEIRA!Q9=0,"",CARTEIRA!Q9) | I8: =IF(CARTEIRA!R9=0,"",CARTEIRA!R9) | Q8: BIME11
A9: =IF(CARTEIRA!J10=0,"",CARTEIRA!J10) | B9: =IF(CARTEIRA!K10=0,"",CARTEIRA!K10) | C9: =IF(CARTEIRA!L10=0,"",CARTEIRA!L10) | D9: =IF(CARTEIRA!M10=0,"",CARTEIRA!M10) | E9: =IF(CARTEIRA!N10=0,"",CARTEIRA!N10) | F9: =IF(CARTEIRA!O10=0,"",CARTEIRA!O10) | G9: =IF(CARTEIRA!P10=0,"",CARTEIRA!P10) | H9: =IF(CARTEIRA!Q10=0,"",CARTEIRA!Q10) | I9: =IF(CARTEIRA!R10=0,"",CARTEIRA!R10) | Q9: LIFE11
A10: =IF(CARTEIRA!J11=0,"",CARTEIRA!J11) | B10: =IF(CARTEIRA!K11=0,"",CARTEIRA!K11) | C10: =IF(CARTEIRA!L11=0,"",CARTEIRA!L11) | D10: =IF(CARTEIRA!M11=0,"",CARTEIRA!M11) | E10: =IF(CARTEIRA!N11=0,"",CARTEIRA!N11) | F10: =IF(CARTEIRA!O11=0,"",CARTEIRA!O11) | G10: =IF(CARTEIRA!P11=0,"",CARTEIRA!P11) | H10: =IF(CARTEIRA!Q11=0,"",CARTEIRA!Q11) | I10: =IF(CARTEIRA!R11=0,"",CARTEIRA!R11) | Q10: PETR4
A11: =IF(CARTEIRA!J12=0,"",CARTEIRA!J12) | B11: =IF(CARTEIRA!K12=0,"",CARTEIRA!K12) | C11: =IF(CARTEIRA!L12=0,"",CARTEIRA!L12) | D11: =IF(CARTEIRA!M12=0,"",CARTEIRA!M12) | E11: =IF(CARTEIRA!N12=0,"",CARTEIRA!N12) | F11: =IF(CARTEIRA!O12=0,"",CARTEIRA!O12) | G11: =IF(CARTEIRA!P12=0,"",CARTEIRA!P12) | H11: =IF(CARTEIRA!Q12=0,"",CARTEIRA!Q12) | I11: =IF(CARTEIRA!R12=0,"",CARTEIRA!R12) | Q11: VALE3
A12: =IF(CARTEIRA!J13=0,"",CARTEIRA!J13) | B12: =IF(CARTEIRA!K13=0,"",CARTEIRA!K13) | C12: =IF(CARTEIRA!L13=0,"",CARTEIRA!L13) | D12: =IF(CARTEIRA!M13=0,"",CARTEIRA!M13) | E12: =IF(CARTEIRA!N13=0,"",CARTEIRA!N13) | F12: =IF(CARTEIRA!O13=0,"",CARTEIRA!O13) | G12: =IF(CARTEIRA!P13=0,"",CARTEIRA!P13) | H12: =IF(CARTEIRA!Q13=0,"",CARTEIRA!Q13) | I12: =IF(CARTEIRA!R13=0,"",CARTEIRA!R13) | Q12: Total Geral
A13: =IF(CARTEIRA!J14=0,"",CARTEIRA!J14) | B13: =IF(CARTEIRA!K14=0,"",CARTEIRA!K14) | C13: =IF(CARTEIRA!L14=0,"",CARTEIRA!L14) | D13: =IF(CARTEIRA!M14=0,"",CARTEIRA!M14) | E13: =IF(CARTEIRA!N14=0,"",CARTEIRA!N14) | F13: =IF(CARTEIRA!O14=0,"",CARTEIRA!O14) | G13: =IF(CARTEIRA!P14=0,"",CARTEIRA!P14) | H13: =IF(CARTEIRA!Q14=0,"",CARTEIRA!Q14) | I13: =IF(CARTEIRA!R14=0,"",CARTEIRA!R14)
A14: =IF(CARTEIRA!J15=0,"",CARTEIRA!J15) | B14: =IF(CARTEIRA!K15=0,"",CARTEIRA!K15) | C14: =IF(CARTEIRA!L15=0,"",CARTEIRA!L15) | D14: =IF(CARTEIRA!M15=0,"",CARTEIRA!M15) | E14: =IF(CARTEIRA!N15=0,"",CARTEIRA!N15) | F14: =IF(CARTEIRA!O15=0,"",CARTEIRA!O15) | G14: =IF(CARTEIRA!P15=0,"",CARTEIRA!P15) | H14: =IF(CARTEIRA!Q15=0,"",CARTEIRA!Q15) | I14: =IF(CARTEIRA!R15=0,"",CARTEIRA!R15)
A15: =IF(CARTEIRA!J16=0,"",CARTEIRA!J16) | B15: =IF(CARTEIRA!K16=0,"",CARTEIRA!K16) | C15: =IF(CARTEIRA!L16=0,"",CARTEIRA!L16) | D15: =IF(CARTEIRA!M16=0,"",CARTEIRA!M16) | E15: =IF(CARTEIRA!N16=0,"",CARTEIRA!N16) | F15: =IF(CARTEIRA!O16=0,"",CARTEIRA!O16) | G15: =IF(CARTEIRA!P16=0,"",CARTEIRA!P16) | H15: =IF(CARTEIRA!Q16=0,"",CARTEIRA!Q16) | I15: =IF(CARTEIRA!R16=0,"",CARTEIRA!R16)
A16: =IF(CARTEIRA!J17=0,"",CARTEIRA!J17) | B16: =IF(CARTEIRA!K17=0,"",CARTEIRA!K17) | C16: =IF(CARTEIRA!L17=0,"",CARTEIRA!L17) | D16: =IF(CARTEIRA!M17=0,"",CARTEIRA!M17) | E16: =IF(CARTEIRA!N17=0,"",CARTEIRA!N17) | F16: =IF(CARTEIRA!O17=0,"",CARTEIRA!O17) | G16: =IF(CARTEIRA!P17=0,"",CARTEIRA!P17) | H16: =IF(CARTEIRA!Q17=0,"",CARTEIRA!Q17) | I16: =IF(CARTEIRA!R17=0,"",CARTEIRA!R17)
A17: =IF(CARTEIRA!J18=0,"",CARTEIRA!J18) | B17: =IF(CARTEIRA!K18=0,"",CARTEIRA!K18) | C17: =IF(CARTEIRA!L18=0,"",CARTEIRA!L18) | D17: =IF(CARTEIRA!M18=0,"",CARTEIRA!M18) | E17: =IF(CARTEIRA!N18=0,"",CARTEIRA!N18) | F17: =IF(CARTEIRA!O18=0,"",CARTEIRA!O18) | G17: =IF(CARTEIRA!P18=0,"",CARTEIRA!P18) | H17: =IF(CARTEIRA!Q18=0,"",CARTEIRA!Q18) | I17: =IF(CARTEIRA!R18=0,"",CARTEIRA!R18)
A18: =IF(CARTEIRA!J19=0,"",CARTEIRA!J19) | B18: =IF(CARTEIRA!K19=0,"",CARTEIRA!K19) | C18: =IF(CARTEIRA!L19=0,"",CARTEIRA!L19) | D18: =IF(CARTEIRA!M19=0,"",CARTEIRA!M19) | E18: =IF(CARTEIRA!N19=0,"",CARTEIRA!N19) | F18: =IF(CARTEIRA!O19=0,"",CARTEIRA!O19) | G18: =IF(CARTEIRA!P19=0,"",CARTEIRA!P19) | H18: =IF(CARTEIRA!Q19=0,"",CARTEIRA!Q19) | I18: =IF(CARTEIRA!R19=0,"",CARTEIRA!R19)
A19: =IF(CARTEIRA!J20=0,"",CARTEIRA!J20) | B19: =IF(CARTEIRA!K20=0,"",CARTEIRA!K20) | C19: =IF(CARTEIRA!L20=0,"",CARTEIRA!L20) | D19: =IF(CARTEIRA!M20=0,"",CARTEIRA!M20) | E19: =IF(CARTEIRA!N20=0,"",CARTEIRA!N20) | F19: =IF(CARTEIRA!O20=0,"",CARTEIRA!O20) | G19: =IF(CARTEIRA!P20=0,"",CARTEIRA!P20) | H19: =IF(CARTEIRA!Q20=0,"",CARTEIRA!Q20) | I19: =IF(CARTEIRA!R20=0,"",CARTEIRA!R20)
A20: =IF(CARTEIRA!J21=0,"",CARTEIRA!J21) | B20: =IF(CARTEIRA!K21=0,"",CARTEIRA!K21) | C20: =IF(CARTEIRA!L21=0,"",CARTEIRA!L21) | D20: =IF(CARTEIRA!M21=0,"",CARTEIRA!M21) | E20: =IF(CARTEIRA!N21=0,"",CARTEIRA!N21) | F20: =IF(CARTEIRA!O21=0,"",CARTEIRA!O21) | G20: =IF(CARTEIRA!P21=0,"",CARTEIRA!P21) | H20: =IF(CARTEIRA!Q21=0,"",CARTEIRA!Q21) | I20: =IF(CARTEIRA!R21=0,"",CARTEIRA!R21)
A21: =IF(CARTEIRA!J22=0,"",CARTEIRA!J22) | B21: =IF(CARTEIRA!K22=0,"",CARTEIRA!K22) | C21: =IF(CARTEIRA!L22=0,"",CARTEIRA!L22) | D21: =IF(CARTEIRA!M22=0,"",CARTEIRA!M22) | E21: =IF(CARTEIRA!N22=0,"",CARTEIRA!N22) | F21: =IF(CARTEIRA!O22=0,"",CARTEIRA!O22) | G21: =IF(CARTEIRA!P22=0,"",CARTEIRA!P22) | H21: =IF(CARTEIRA!Q22=0,"",CARTEIRA!Q22) | I21: =IF(CARTEIRA!R22=0,"",CARTEIRA!R22)
A22: =IF(CARTEIRA!J23=0,"",CARTEIRA!J23) | B22: =IF(CARTEIRA!K23=0,"",CARTEIRA!K23) | C22: =IF(CARTEIRA!L23=0,"",CARTEIRA!L23) | D22: =IF(CARTEIRA!M23=0,"",CARTEIRA!M23) | E22: =IF(CARTEIRA!N23=0,"",CARTEIRA!N23) | F22: =IF(CARTEIRA!O23=0,"",CARTEIRA!O23) | G22: =IF(CARTEIRA!P23=0,"",CARTEIRA!P23) | H22: =IF(CARTEIRA!Q23=0,"",CARTEIRA!Q23) | I22: =IF(CARTEIRA!R23=0,"",CARTEIRA!R23)
A23: =IF(CARTEIRA!J24=0,"",CARTEIRA!J24) | B23: =IF(CARTEIRA!K24=0,"",CARTEIRA!K24) | C23: =IF(CARTEIRA!L24=0,"",CARTEIRA!L24) | D23: =IF(CARTEIRA!M24=0,"",CARTEIRA!M24) | E23: =IF(CARTEIRA!N24=0,"",CARTEIRA!N24) | F23: =IF(CARTEIRA!O24=0,"",CARTEIRA!O24) | G23: =IF(CARTEIRA!P24=0,"",CARTEIRA!P24) | H23: =IF(CARTEIRA!Q24=0,"",CARTEIRA!Q24) | I23: =IF(CARTEIRA!R24=0,"",CARTEIRA!R24)
